Workbook

Sheet Round 1
A1: Round 1 | B1: 1 | C1: 2 | D1: 3 | E1: 4 | F1: 5 | G1: 6 | H1: 7 | I1: 8 | J1: 9 | K1: 10 | L1: 11 | M1: 12 | N1: 13 | O1: 14 | P1: 15 | AK1: Space position | AZ1: Names | BO1: Points | CD1: 98 | CE1: =counta(CE2:CE100) -> 21 | CF1: Points
A2: Description | B2: Snowmobile - Beach Cup - The Dunes | C2: Mono - Bumpy Ride Cup - Rough Road | D2: Rally Car - Green Cup - Spartan Racing | E2: Formula - Big Air Cup - Landing Drive | F2: Racing Truck - Spring City - Heat Club | G2: Hot Rod - Bumpy Ride Cup - Rough Road | J2: Snowmobile - Beach Cup - The Dunes | K2: Mono - Bumpy Ride Cup - Rough Road | L2: Rally Car - Green Cup - Spartan Racing | M2: Formula - Big Air Cup - Landing Drive | N2: Racing Truck - Spring City - Heat Club | O2: Hot Rod - Bumpy Ride Cup - Rough Road | P2: Hot Rod - Bumpy Ride Cup - Rough Road | S2: =A1 -> Round 1 | T2: Total | U2: =B1 -> 1 | V2: =C1 -> 2 | W2: =D1 -> 3 | X2: =E1 -> 4 | Y2: =F1 -> 5 | Z2: =G1 -> 6 | AA2: =H1 -> 7 | AB2: =I1 -> 8 | ... AI2: =P1 -> 15 | AK2: =B1 -> 1 | AL2: 2 | AM2: 3 | AN2: 4 | AO2: 5 | AP2: 6 | AQ2: 7 | AR2: =I1 -> 8 | AS2: 8 | AT2: 9 | AU2: 10 | AV2: 11 | AW2: 12 | AX2: 13 | AY2: =P1 -> 15 | AZ2: 1 | BA2: 2 | BB2: 3 | BC2: 4 | BD2: 5 | BE2: 6 | BF2: 7 | BG2: 8 | BH2: 9 | BI2: 10 | BJ2: 11 | BK2: 12 | BL2: 13 | BM2: 14 | BN2: 15 | BO2: 1 | BP2: 2 | BQ2: 3 | BR2: 4 | BS2: 5 | BT2: 6 | BU2: 7 | BV2: 8 | BW2: 9 | BX2: 10 | BY2: 11 | BZ2: 12 | CA2: 13 | CB2: 14 | CC2: 15 | CD2: Names | CE2: Name | CF2: Total | CG2: 1 | CH2: =CG2+1 -> 2 | CI2: =CH2+1 -> 3 | CJ2: =CI2+1 -> 4 | CK2: =CJ2+1 -> 5 | CL2: =CK2+1 -> 6 | CM2: =CL2+1 -> 7 | CN2: =CM2+1 -> 8 | CO2: =CN2+1 -> 9 | ... CU2: =CT2+1 -> 15
A3: Scores | B3: Getzata 19.839 | C3: Getzata 12.901 | D3: Getzata 21.993 | E3: Ollie 11.794 | F3: Leif 28.909 | G3: Jesko 9.495 | I3: Getzata 27.188 | J3: Getzata 19.839 | K3: Getzata 12.901 | L3: Getzata 21.993 | M3: Ollie 11.794 | N3: Leif 28.909 | O3: Jesko 9.495 | P3: Jesko 9.495 | R3: =if(T3="","",rank(T3,T:T,false)) -> 1 | S3: {=sort(offset(CE3,,,CE1-1,17),offset(CF3,,,CE1-1,1),)} -> Getzata | T3: 1609 | U3: 119 | V3: 119 | W3: 119 | X3: 106 | Y3: 108 | Z3: 116 | AA3: 0 | AB3: 119 | AC3: 119 | AD3: 119 | AE3: 119 | AF3: 106 | AG3: 108 | AH3: 116 | AI3: 116 | AK3: =iferror(find(" ",B3) ,"") -> 8 | AL3: =iferror(find(" ",C3) ,"") -> 8 | AM3: =iferror(find(" ",D3) ,"") -> 8 | AN3: =iferror(find(" ",E3) ,"") -> 6 | AO3: =iferror(find(" ",F3) ,"") -> 5 | AP3: =iferror(find(" ",G3) ,"") -> 6 | AQ3: =iferror(find(" ",H3) ,"") | AR3: =iferror(find(" ",I3) ,"") -> 8 | ... AY3: =iferror(find(" ",P3) ,"") -> 6 | AZ3: =if(and(len(B3)>0,AK3=""),B3,iferror(left(B3, AK3-1),"")) -> Getzata | BA3: =if(and(len(C3)>0,AL3=""),C3,iferror(left(C3, AL3-1),"")) -> Getzata | BB3: =if(and(len(D3)>0,AM3=""),D3,iferror(left(D3, AM3-1),"")) -> Getzata | BC3: =if(and(len(E3)>0,AN3=""),E3,iferror(left(E3, AN3-1),"")) -> Ollie | BD3: =if(and(len(F3)>0,AO3=""),F3,iferror(left(F3, AO3-1),"")) -> Leif | BE3: =if(and(len(G3)>0,AP3=""),G3,iferror(left(G3, AP3-1),"")) -> Jesko | BF3: =if(and(len(H3)>0,AQ3=""),H3,iferror(left(H3, AQ3-1),"")) | BG3: =if(and(len(I3)>0,AR3=""),I3,iferror(left(I3, AR3-1),"")) -> Getzata | ... BN3: =if(and(len(P3)>0,AY3=""),P3,iferror(left(P3, AY3-1),"")) -> Jesko | BO3: {=IF(AZ3="","",INDEX(Points!$A:$A,row()-2))} -> 119 | BP3: {=IF(BA3="","",INDEX(Points!$A:$A,row()-2))} -> 119 | BQ3: {=IF(BB3="","",INDEX(Points!$A:$A,row()-2))} -> 119 | BR3: {=IF(BC3="","",INDEX(Points!$A:$A,row()-2))} -> 119 | BS3: {=IF(BD3="","",INDEX(Points!$A:$A,row()-2))} -> 119 | BT3: {=IF(BE3="","",INDEX(Points!$A:$A,row()-2))} -> 119 | BU3: {=IF(BF3="","",INDEX(Points!$A:$A,row()-2))} | BV3: {=IF(BG3="","",INDEX(Points!$A:$A,row()-2))} -> 119 | ... CC3: {=IF(BN3="","",INDEX(Points!$A:$A,row()-2))} -> 119 | CD3: {=index($AZ$3:$BN$100,Mod(row()-3,$CD$1)+1,int((row()-3)/$CD$1)+1)} -> Getzata | CE3: =IFERROR(__xludf.DUMMYFUNCTION("UNIQUE(filter(CD3:CD3000,not(CD3:CD3000="""")))"),"Getzata") -> Getzata | CF3: =if(CE3="","",sum(CG3:CU3)) -> 1609 | CG3: =if($CE3="","",sumif(AZ:AZ,$CE3,BO:BO)) -> 119 | CH3: =if($CE3="","",sumif(BA:BA,$CE3,BP:BP)) -> 119 | CI3: =if($CE3="","",sumif(BB:BB,$CE3,BQ:BQ)) -> 119 | CJ3: =if($CE3="","",sumif(BC:BC,$CE3,BR:BR)) -> 106 | CK3: =if($CE3="","",sumif(BD:BD,$CE3,BS:BS)) -> 108 | CL3: =if($CE3="","",sumif(BE:BE,$CE3,BT:BT)) -> 116 | CM3: =if($CE3="","",sumif(BF:BF,$CE3,BU:BU)) -> 0 | CN3: =if($CE3="","",sumif(BG:BG,$CE3,BV:BV)) -> 119 | CO3: =if($CE3="","",sumif(BH:BH,$CE3,BW:BW)) -> 119 | CP3: =if($CE3="","",sumif(BI:BI,$CE3,BX:BX)) -> 119 | CQ3: =if($CE3="","",sumif(BJ:BJ,$CE3,BY:BY)) -> 119 | CR3: =if($CE3="","",sumif(BK:BK,$CE3,BZ:BZ)) -> 106 | CS3: =if($CE3="","",sumif(BL:BL,$CE3,CA:CA)) -> 108 | CT3: =if($CE3="","",sumif(BM:BM,$CE3,CB:CB)) -> 116 | CU3: =if($CE3="","",sumif(BN:BN,$CE3,CC:CC)) -> 116
B4: Fozzy 20.548 | C4: Fozzy 13.351 | D4: Boodles 22.191 | E4: DropX 12.619 | F4: Fozzy 29.188 | G4: Getzata 9.543 | J4: Fozzy 20.548 | K4: Fozzy 13.351 | L4: Boodles 22.191 | M4: DropX 12.619 | N4: Fozzy 29.188 | O4: Getzata 9.543 | P4: Getzata 9.543 | R4: =if(T4="","",rank(T4,T:T,false)) -> 2 | S4: Fozzy | T4: 1472 | U4: 116 | V4: 116 | W4: 110 | X4: 113 | Y4: 116 | Z4: 110 | AA4: 0 | AB4: 0 | AC4: 116 | AD4: 116 | AE4: 110 | AF4: 113 | AG4: 116 | AH4: 110 | AI4: 110 | AK4: =iferror(find(" ",B4) ,"") -> 6 | AL4: =iferror(find(" ",C4) ,"") -> 6 | AM4: =iferror(find(" ",D4) ,"") -> 8 | AN4: =iferror(find(" ",E4) ,"") -> 6 | AO4: =iferror(find(" ",F4) ,"") -> 6 | AP4: =iferror(find(" ",G4) ,"") -> 8 | AQ4: =iferror(find(" ",H4) ,"") | AR4: =iferror(find(" ",I4) ,"") | ... AY4: =iferror(find(" ",P4) ,"") -> 8 | AZ4: =if(and(len(B4)>0,AK4=""),B4,iferror(left(B4, AK4-1),"")) -> Fozzy | BA4: =if(and(len(C4)>0,AL4=""),C4,iferror(left(C4, AL4-1),"")) -> Fozzy | BB4: =if(and(len(D4)>0,AM4=""),D4,iferror(left(D4, AM4-1),"")) -> Boodles | BC4: =if(and(len(E4)>0,AN4=""),E4,iferror(left(E4, AN4-1),"")) -> DropX | BD4: =if(and(len(F4)>0,AO4=""),F4,iferror(left(F4, AO4-1),"")) -> Fozzy | BE4: =if(and(len(G4)>0,AP4=""),G4,iferror(left(G4, AP4-1),"")) -> Getzata | BF4: =if(and(len(H4)>0,AQ4=""),H4,iferror(left(H4, AQ4-1),"")) | BG4: =if(and(len(I4)>0,AR4=""),I4,iferror(left(I4, AR4-1),"")) | ... BN4: =if(and(len(P4)>0,AY4=""),P4,iferror(left(P4, AY4-1),"")) -> Getzata | BO4: {=IF(AZ4="","",INDEX(Points!$A:$A,row()-2))} -> 116 | BP4: {=IF(BA4="","",INDEX(Points!$A:$A,row()-2))} -> 116 | BQ4: {=IF(BB4="","",INDEX(Points!$A:$A,row()-2))} -> 116 | BR4: {=IF(BC4="","",INDEX(Points!$A:$A,row()-2))} -> 116 | BS4: {=IF(BD4="","",INDEX(Points!$A:$A,row()-2))} -> 116 | BT4: {=IF(BE4="","",INDEX(Points!$A:$A,row()-2))} -> 116 | BU4: {=IF(BF4="","",INDEX(Points!$A:$A,row()-2))} | BV4: {=IF(BG4="","",INDEX(Points!$A:$A,row()-2))} | ... CC4: {=IF(BN4="","",INDEX(Points!$A:$A,row()-2))} -> 116 | CD4: =index($AZ$3:$BF$100,Mod(row()-3,$CD$1)+1,int((row()-3)/$CD$1)+1) -> Fozzy | CE4: =IFERROR(__xludf.DUMMYFUNCTION("""COMPUTED_VALUE"""),"Fozzy") -> Fozzy | CF4: =if(CE4="","",sum(CG4:CU4)) -> 1472 | CG4: =if($CE4="","",sumif(AZ:AZ,$CE4,BO:BO)) -> 116 | CH4: =if($CE4="","",sumif(BA:BA,$CE4,BP:BP)) -> 116 | CI4: =if($CE4="","",sumif(BB:BB,$CE4,BQ:BQ)) -> 110 | CJ4: =if($CE4="","",sumif(BC:BC,$CE4,BR:BR)) -> 113 | CK4: =if($CE4="","",sumif(BD:BD,$CE4,BS:BS)) -> 116 | CL4: =if($CE4="","",sumif(BE:BE,$CE4,BT:BT)) -> 110 | CM4: =if($CE4="","",sumif(BF:BF,$CE4,BU:BU)) -> 0 | CN4: =if($CE4="","",sumif(BG:BG,$CE4,BV:BV)) -> 0 | CO4: =if($CE4="","",sumif(BH:BH,$CE4,BW:BW)) -> 116 | CP4: =if($CE4="","",sumif(BI:BI,$CE4,BX:BX)) -> 116 | CQ4: =if($CE4="","",sumif(BJ:BJ,$CE4,BY:BY)) -> 110 | CR4: =if($CE4="","",sumif(BK:BK,$CE4,BZ:BZ)) -> 113 | CS4: =if($CE4="","",sumif(BL:BL,$CE4,CA:CA)) -> 116 | CT4: =if($CE4="","",sumif(BM:BM,$CE4,CB:CB)) -> 110 | CU4: =if($CE4="","",sumif(BN:BN,$CE4,CC:CC)) -> 110
B5: GotGoing 22.420 | D5: Leif 22.295 | E5: Fozzy 12.754 | F5: GotGoing 29.792 | G5: Nightmare 9.649 | J5: GotGoing 22.420 | L5: Leif 22.295 | M5: Fozzy 12.754 | N5: GotGoing 29.792 | O5: Nightmare 9.649 | P5: Nightmare 9.649 | R5: =if(T5="","",rank(T5,T:T,false)) -> 3 | S5: Nightmare | T5: 763 | U5: 0 | V5: 0 | W5: 106 | X5: 0 | Y5: 106 | Z5: 113 | AA5: 0 | AB5: 0 | AC5: 0 | AD5: 0 | AE5: 106 | AF5: 0 | AG5: 106 | AH5: 113 | AI5: 113 | AK5: =iferror(find(" ",B5) ,"") -> 9 | AL5: =iferror(find(" ",C5) ,"") | AM5: =iferror(find(" ",D5) ,"") -> 5 | AN5: =iferror(find(" ",E5) ,"") -> 6 | AO5: =iferror(find(" ",F5) ,"") -> 9 | AP5: =iferror(find(" ",G5) ,"") -> 10 | AQ5: =iferror(find(" ",H5) ,"") | AR5: =iferror(find(" ",I5) ,"") | ... AY5: =iferror(find(" ",P5) ,"") -> 10 | AZ5: =if(and(len(B5)>0,AK5=""),B5,iferror(left(B5, AK5-1),"")) -> GotGoing | BA5: =if(and(len(C5)>0,AL5=""),C5,iferror(left(C5, AL5-1),"")) | BB5: =if(and(len(D5)>0,AM5=""),D5,iferror(left(D5, AM5-1),"")) -> Leif | BC5: =if(and(len(E5)>0,AN5=""),E5,iferror(left(E5, AN5-1),"")) -> Fozzy | BD5: =if(and(len(F5)>0,AO5=""),F5,iferror(left(F5, AO5-1),"")) -> GotGoing | BE5: =if(and(len(G5)>0,AP5=""),G5,iferror(left(G5, AP5-1),"")) -> Nightmare | BF5: =if(and(len(H5)>0,AQ5=""),H5,iferror(left(H5, AQ5-1),"")) | BG5: =if(and(len(I5)>0,AR5=""),I5,iferror(left(I5, AR5-1),"")) | ... BN5: =if(and(len(P5)>0,AY5=""),P5,iferror(left(P5, AY5-1),"")) -> Nightmare | BO5: {=IF(AZ5="","",INDEX(Points!$A:$A,row()-2))} -> 113 | BP5: {=IF(BA5="","",INDEX(Points!$A:$A,row()-2))} | BQ5: {=IF(BB5="","",INDEX(Points!$A:$A,row()-2))} -> 113 | BR5: {=IF(BC5="","",INDEX(Points!$A:$A,row()-2))} -> 113 | BS5: {=IF(BD5="","",INDEX(Points!$A:$A,row()-2))} -> 113 | BT5: {=IF(BE5="","",INDEX(Points!$A:$A,row()-2))} -> 113 | BU5: {=IF(BF5="","",INDEX(Points!$A:$A,row()-2))} | BV5: {=IF(BG5="","",INDEX(Points!$A:$A,row()-2))} | ... CC5: {=IF(BN5="","",INDEX(Points!$A:$A,row()-2))} -> 113 | CD5: =index($AZ$3:$BF$100,Mod(row()-3,$CD$1)+1,int((row()-3)/$CD$1)+1) -> GotGoing | CE5: =IFERROR(__xludf.DUMMYFUNCTION("""COMPUTED_VALUE"""),"GotGoing") -> GotGoing | CF5: =if(CE5="","",sum(CG5:CU5)) -> 755 | CG5: =if($CE5="","",sumif(AZ:AZ,$CE5,BO:BO)) -> 113 | CH5: =if($CE5="","",sumif(BA:BA,$CE5,BP:BP)) -> 0 | CI5: =if($CE5="","",sumif(BB:BB,$CE5,BQ:BQ)) -> 0 | CJ5: =if($CE5="","",sumif(BC:BC,$CE5,BR:BR)) -> 0 | CK5: =if($CE5="","",sumif(BD:BD,$CE5,BS:BS)) -> 113 | CL5: =if($CE5="","",sumif(BE:BE,$CE5,BT:BT)) -> 101 | CM5: =if($CE5="","",sumif(BF:BF,$CE5,BU:BU)) -> 0 | CN5: =if($CE5="","",sumif(BG:BG,$CE5,BV:BV)) -> 0 | CO5: =if($CE5="","",sumif(BH:BH,$CE5,BW:BW)) -> 113 | CP5: =if($CE5="","",sumif(BI:BI,$CE5,BX:BX)) -> 0 | CQ5: =if($CE5="","",sumif(BJ:BJ,$CE5,BY:BY)) -> 0 | CR5: =if($CE5="","",sumif(BK:BK,$CE5,BZ:BZ)) -> 0 | CS5: =if($CE5="","",sumif(BL:BL,$CE5,CA:CA)) -> 113 | CT5: =if($CE5="","",sumif(BM:BM,$CE5,CB:CB)) -> 101 | CU5: =if($CE5="","",sumif(BN:BN,$CE5,CC:CC)) -> 101
D6: Fozzy 22.831 | E6: Vision 13.233 | F6: Fishy 30.463 | G6: Fozzy 9.680 | L6: Fozzy 22.831 | M6: Vision 13.233 | N6: Fishy 30.463 | O6: Fozzy 9.680 | P6: Fozzy 9.680 | R6: =if(T6="","",rank(T6,T:T,false)) -> 3 | S6: Jesko | T6: 763 | U6: 0 | V6: 0 | W6: 0 | X6: 101 | Y6: 102 | Z6: 119 | AA6: 0 | AB6: 0 | AC6: 0 | AD6: 0 | AE6: 0 | AF6: 101 | AG6: 102 | AH6: 119 | AI6: 119 | AK6: =iferror(find(" ",B6) ,"") | AL6: =iferror(find(" ",C6) ,"") | AM6: =iferror(find(" ",D6) ,"") -> 6 | AN6: =iferror(find(" ",E6) ,"") -> 7 | AO6: =iferror(find(" ",F6) ,"") -> 6 | AP6: =iferror(find(" ",G6) ,"") -> 6 | AQ6: =iferror(find(" ",H6) ,"") | AR6: =iferror(find(" ",I6) ,"") | ... AY6: =iferror(find(" ",P6) ,"") -> 6 | AZ6: =if(and(len(B6)>0,AK6=""),B6,iferror(left(B6, AK6-1),"")) | BA6: =if(and(len(C6)>0,AL6=""),C6,iferror(left(C6, AL6-1),"")) | BB6: =if(and(len(D6)>0,AM6=""),D6,iferror(left(D6, AM6-1),"")) -> Fozzy | BC6: =if(and(len(E6)>0,AN6=""),E6,iferror(left(E6, AN6-1),"")) -> Vision | BD6: =if(and(len(F6)>0,AO6=""),F6,iferror(left(F6, AO6-1),"")) -> Fishy | BE6: =if(and(len(G6)>0,AP6=""),G6,iferror(left(G6, AP6-1),"")) -> Fozzy | BF6: =if(and(len(H6)>0,AQ6=""),H6,iferror(left(H6, AQ6-1),"")) | BG6: =if(and(len(I6)>0,AR6=""),I6,iferror(left(I6, AR6-1),"")) | ... BN6: =if(and(len(P6)>0,AY6=""),P6,iferror(left(P6, AY6-1),"")) -> Fozzy | BO6: {=IF(AZ6="","",INDEX(Points!$A:$A,row()-2))} | BP6: {=IF(BA6="","",INDEX(Points!$A:$A,row()-2))} | BQ6: {=IF(BB6="","",INDEX(Points!$A:$A,row()-2))} -> 110 | BR6: {=IF(BC6="","",INDEX(Points!$A:$A,row()-2))} -> 110 | BS6: {=IF(BD6="","",INDEX(Points!$A:$A,row()-2))} -> 110 | BT6: {=IF(BE6="","",INDEX(Points!$A:$A,row()-2))} -> 110 | BU6: {=IF(BF6="","",INDEX(Points!$A:$A,row()-2))} | BV6: {=IF(BG6="","",INDEX(Points!$A:$A,row()-2))} | ... CC6: {=IF(BN6="","",INDEX(Points!$A:$A,row()-2))} -> 110 | CD6: =index($AZ$3:$BF$100,Mod(row()-3,$CD$1)+1,int((row()-3)/$CD$1)+1) | CE6: =IFERROR(__xludf.DUMMYFUNCTION("""COMPUTED_VALUE"""),"Boodles") -> Boodles | CF6: =if(CE6="","",sum(CG6:CU6)) -> 440 | CG6: =if($CE6="","",sumif(AZ:AZ,$CE6,BO:BO)) -> 0 | CH6: =if($CE6="","",sumif(BA:BA,$CE6,BP:BP)) -> 0 | CI6: =if($CE6="","",sumif(BB:BB,$CE6,BQ:BQ)) -> 116 | CJ6: =if($CE6="","",sumif(BC:BC,$CE6,BR:BR)) -> 104 | CK6: =if($CE6="","",sumif(BD:BD,$CE6,BS:BS)) -> 0 | CL6: =if($CE6="","",sumif(BE:BE,$CE6,BT:BT)) -> 0 | CM6: =if($CE6="","",sumif(BF:BF,$CE6,BU:BU)) -> 0 | CN6: =if($CE6="","",sumif(BG:BG,$CE6,BV:BV)) -> 0 | CO6: =if($CE6="","",sumif(BH:BH,$CE6,BW:BW)) -> 0 | CP6: =if($CE6="","",sumif(BI:BI,$CE6,BX:BX)) -> 0 | CQ6: =if($CE6="","",sumif(BJ:BJ,$CE6,BY:BY)) -> 116 | CR6: =if($CE6="","",sumif(BK:BK,$CE6,BZ:BZ)) -> 104 | CS6: =if($CE6="","",sumif(BL:BL,$CE6,CA:CA)) -> 0 | CT6: =if($CE6="","",sumif(BM:BM,$CE6,CB:CB)) -> 0 | CU6: =if($CE6="","",sumif(BN:BN,$CE6,CC:CC)) -> 0
D7: HeisRisen 23.036 | E7: Retep 13.796 | F7: Getzata 30.567 | G7: DGG 9.866 | L7: HeisRisen 23.036 | M7: Retep 13.796 | N7: Getzata 30.567 | O7: DGG 9.866 | P7: DGG 9.866 | R7: =if(T7="","",rank(T7,T:T,false)) -> 5 | S7: GotGoing | T7: 755 | U7: 113 | V7: 0 | W7: 0 | X7: 0 | Y7: 113 | Z7: 101 | AA7: 0 | AB7: 0 | AC7: 113 | AD7: 0 | AE7: 0 | AF7: 0 | AG7: 113 | AH7: 101 | AI7: 101 | AK7: =iferror(find(" ",B7) ,"") | AL7: =iferror(find(" ",C7) ,"") | AM7: =iferror(find(" ",D7) ,"") -> 10 | AN7: =iferror(find(" ",E7) ,"") -> 6 | AO7: =iferror(find(" ",F7) ,"") -> 8 | AP7: =iferror(find(" ",G7) ,"") -> 4 | AQ7: =iferror(find(" ",H7) ,"") | AR7: =iferror(find(" ",I7) ,"") | ... AY7: =iferror(find(" ",P7) ,"") -> 4 | AZ7: =if(and(len(B7)>0,AK7=""),B7,iferror(left(B7, AK7-1),"")) | BA7: =if(and(len(C7)>0,AL7=""),C7,iferror(left(C7, AL7-1),"")) | BB7: =if(and(len(D7)>0,AM7=""),D7,iferror(left(D7, AM7-1),"")) -> HeisRisen | BC7: =if(and(len(E7)>0,AN7=""),E7,iferror(left(E7, AN7-1),"")) -> Retep | BD7: =if(and(len(F7)>0,AO7=""),F7,iferror(left(F7, AO7-1),"")) -> Getzata | BE7: =if(and(len(G7)>0,AP7=""),G7,iferror(left(G7, AP7-1),"")) -> DGG | BF7: =if(and(len(H7)>0,AQ7=""),H7,iferror(left(H7, AQ7-1),"")) | BG7: =if(and(len(I7)>0,AR7=""),I7,iferror(left(I7, AR7-1),"")) | ... BN7: =if(and(len(P7)>0,AY7=""),P7,iferror(left(P7, AY7-1),"")) -> DGG | BO7: {=IF(AZ7="","",INDEX(Points!$A:$A,row()-2))} | BP7: {=IF(BA7="","",INDEX(Points!$A:$A,row()-2))} | BQ7: {=IF(BB7="","",INDEX(Points!$A:$A,row()-2))} -> 108 | BR7: {=IF(BC7="","",INDEX(Points!$A:$A,row()-2))} -> 108 | BS7: {=IF(BD7="","",INDEX(Points!$A:$A,row()-2))} -> 108 | BT7: {=IF(BE7="","",INDEX(Points!$A:$A,row()-2))} -> 108 | BU7: {=IF(BF7="","",INDEX(Points!$A:$A,row()-2))} | BV7: {=IF(BG7="","",INDEX(Points!$A:$A,row()-2))} | ... CC7: {=IF(BN7="","",INDEX(Points!$A:$A,row()-2))} -> 108 | CD7: =index($AZ$3:$BF$100,Mod(row()-3,$CD$1)+1,int((row()-3)/$CD$1)+1) | CE7: =IFERROR(__xludf.DUMMYFUNCTION("""COMPUTED_VALUE"""),"Leif") -> Leif | CF7: =if(CE7="","",sum(CG7:CU7)) -> 464 | CG7: =if($CE7="","",sumif(AZ:AZ,$CE7,BO:BO)) -> 0 | CH7: =if($CE7="","",sumif(BA:BA,$CE7,BP:BP)) -> 0 | CI7: =if($CE7="","",sumif(BB:BB,$CE7,BQ:BQ)) -> 113 | CJ7: =if($CE7="","",sumif(BC:BC,$CE7,BR:BR)) -> 0 | CK7: =if($CE7="","",sumif(BD:BD,$CE7,BS:BS)) -> 119 | CL7: =if($CE7="","",sumif(BE:BE,$CE7,BT:BT)) -> 0 | CM7: =if($CE7="","",sumif(BF:BF,$CE7,BU:BU)) -> 0 | CN7: =if($CE7="","",sumif(BG:BG,$CE7,BV:BV)) -> 0 | CO7: =if($CE7="","",sumif(BH:BH,$CE7,BW:BW)) -> 0 | CP7: =if($CE7="","",sumif(BI:BI,$CE7,BX:BX)) -> 0 | CQ7: =if($CE7="","",sumif(BJ:BJ,$CE7,BY:BY)) -> 113 | CR7: =if($CE7="","",sumif(BK:BK,$CE7,BZ:BZ)) -> 0 | CS7: =if($CE7="","",sumif(BL:BL,$CE7,CA:CA)) -> 119 | CT7: =if($CE7="","",sumif(BM:BM,$CE7,CB:CB)) -> 0 | CU7: =if($CE7="","",sumif(BN:BN,$CE7,CC:CC)) -> 0
D8: Nightmare 23.536 | E8: Getzata 14.334 | F8: Nightmare 31.074 | G8: HeisRisen 9.994 | L8: Nightmare 23.536 | M8: Getzata 14.334 | N8: Nightmare 31.074 | O8: HeisRisen 9.994 | P8: HeisRisen 9.994 | R8: =if(T8="","",rank(T8,T:T,false)) -> 6 | S8: Retep | T8: 730 | U8: 0 | V8: 0 | W8: 104 | X8: 108 | Y8: 0 | Z8: 102 | AA8: 0 | AB8: 0 | AC8: 0 | AD8: 0 | AE8: 104 | AF8: 108 | AG8: 0 | AH8: 102 | AI8: 102 | AK8: =iferror(find(" ",B8) ,"") | AL8: =iferror(find(" ",C8) ,"") | AM8: =iferror(find(" ",D8) ,"") -> 10 | AN8: =iferror(find(" ",E8) ,"") -> 8 | AO8: =iferror(find(" ",F8) ,"") -> 10 | AP8: =iferror(find(" ",G8) ,"") -> 10 | AQ8: =iferror(find(" ",H8) ,"") | AR8: =iferror(find(" ",I8) ,"") | ... AY8: =iferror(find(" ",P8) ,"") -> 10 | AZ8: =if(and(len(B8)>0,AK8=""),B8,iferror(left(B8, AK8-1),"")) | BA8: =if(and(len(C8)>0,AL8=""),C8,iferror(left(C8, AL8-1),"")) | BB8: =if(and(len(D8)>0,AM8=""),D8,iferror(left(D8, AM8-1),"")) -> Nightmare | BC8: =if(and(len(E8)>0,AN8=""),E8,iferror(left(E8, AN8-1),"")) -> Getzata | BD8: =if(and(len(F8)>0,AO8=""),F8,iferror(left(F8, AO8-1),"")) -> Nightmare | BE8: =if(and(len(G8)>0,AP8=""),G8,iferror(left(G8, AP8-1),"")) -> HeisRisen | BF8: =if(and(len(H8)>0,AQ8=""),H8,iferror(left(H8, AQ8-1),"")) | BG8: =if(and(len(I8)>0,AR8=""),I8,iferror(left(I8, AR8-1),"")) | ... BN8: =if(and(len(P8)>0,AY8=""),P8,iferror(left(P8, AY8-1),"")) -> HeisRisen | BO8: {=IF(AZ8="","",INDEX(Points!$A:$A,row()-2))} | BP8: {=IF(BA8="","",INDEX(Points!$A:$A,row()-2))} | BQ8: {=IF(BB8="","",INDEX(Points!$A:$A,row()-2))} -> 106 | BR8: {=IF(BC8="","",INDEX(Points!$A:$A,row()-2))} -> 106 | BS8: {=IF(BD8="","",INDEX(Points!$A:$A,row()-2))} -> 106 | BT8: {=IF(BE8="","",INDEX(Points!$A:$A,row()-2))} -> 106 | BU8: {=IF(BF8="","",INDEX(Points!$A:$A,row()-2))} | BV8: {=IF(BG8="","",INDEX(Points!$A:$A,row()-2))} | ... CC8: {=IF(BN8="","",INDEX(Points!$A:$A,row()-2))} -> 106 | CD8: =index($AZ$3:$BF$100,Mod(row()-3,$CD$1)+1,int((row()-3)/$CD$1)+1) | CE8: =IFERROR(__xludf.DUMMYFUNCTION("""COMPUTED_VALUE"""),"HeisRisen") -> HeisRisen | CF8: =if(CE8="","",sum(CG8:CU8)) -> 534 | CG8: =if($CE8="","",sumif(AZ:AZ,$CE8,BO:BO)) -> 0 | CH8: =if($CE8="","",sumif(BA:BA,$CE8,BP:BP)) -> 0 | CI8: =if($CE8="","",sumif(BB:BB,$CE8,BQ:BQ)) -> 108 | CJ8: =if($CE8="","",sumif(BC:BC,$CE8,BR:BR)) -> 0 | CK8: =if($CE8="","",sumif(BD:BD,$CE8,BS:BS)) -> 0 | CL8: =if($CE8="","",sumif(BE:BE,$CE8,BT:BT)) -> 106 | CM8: =if($CE8="","",sumif(BF:BF,$CE8,BU:BU)) -> 0 | CN8: =if($CE8="","",sumif(BG:BG,$CE8,BV:BV)) -> 0 | CO8: =if($CE8="","",sumif(BH:BH,$CE8,BW:BW)) -> 0 | CP8: =if($CE8="","",sumif(BI:BI,$CE8,BX:BX)) -> 0 | CQ8: =if($CE8="","",sumif(BJ:BJ,$CE8,BY:BY)) -> 108 | CR8: =if($CE8="","",sumif(BK:BK,$CE8,BZ:BZ)) -> 0 | CS8: =if($CE8="","",sumif(BL:BL,$CE8,CA:CA)) -> 0 | CT8: =if($CE8="","",sumif(BM:BM,$CE8,CB:CB)) -> 106 | CU8: =if($CE8="","",sumif(BN:BN,$CE8,CC:CC)) -> 106
D9: Retep 24.175 | E9: Boodles 15.974 | F9: Gutterbutter 31.722 | G9: Gutterbutter 10.048 | L9: Retep 24.175 | M9: Boodles 15.974 | N9: Gutterbutter 31.722 | O9: Gutterbutter 10.048 | P9: Gutterbutter 10.048 | R9: =if(T9="","",rank(T9,T:T,false)) -> 7 | S9: Gutterbutter | T9: 724 | U9: 0 | V9: 0 | W9: 0 | X9: 102 | Y9: 104 | Z9: 104 | AA9: 0 | AB9: 0 | AC9: 0 | AD9: 0 | AE9: 0 | AF9: 102 | AG9: 104 | AH9: 104 | AI9: 104 | AK9: =iferror(find(" ",B9) ,"") | AL9: =iferror(find(" ",C9) ,"") | AM9: =iferror(find(" ",D9) ,"") -> 6 | AN9: =iferror(find(" ",E9) ,"") -> 8 | AO9: =iferror(find(" ",F9) ,"") -> 13 | AP9: =iferror(find(" ",G9) ,"") -> 13 | AQ9: =iferror(find(" ",H9) ,"") | AR9: =iferror(find(" ",I9) ,"") | ... AY9: =iferror(find(" ",P9) ,"") -> 13 | AZ9: =if(and(len(B9)>0,AK9=""),B9,iferror(left(B9, AK9-1),"")) | BA9: =if(and(len(C9)>0,AL9=""),C9,iferror(left(C9, AL9-1),"")) | BB9: =if(and(len(D9)>0,AM9=""),D9,iferror(left(D9, AM9-1),"")) -> Retep | BC9: =if(and(len(E9)>0,AN9=""),E9,iferror(left(E9, AN9-1),"")) -> Boodles | BD9: =if(and(len(F9)>0,AO9=""),F9,iferror(left(F9, AO9-1),"")) -> Gutterbutter | BE9: =if(and(len(G9)>0,AP9=""),G9,iferror(left(G9, AP9-1),"")) -> Gutterbutter | BF9: =if(and(len(H9)>0,AQ9=""),H9,iferror(left(H9, AQ9-1),"")) | BG9: =if(and(len(I9)>0,AR9=""),I9,iferror(left(I9, AR9-1),"")) | ... BN9: =if(and(len(P9)>0,AY9=""),P9,iferror(left(P9, AY9-1),"")) -> Gutterbutter | BO9: {=IF(AZ9="","",INDEX(Points!$A:$A,row()-2))} | BP9: {=IF(BA9="","",INDEX(Points!$A:$A,row()-2))} | BQ9: {=IF(BB9="","",INDEX(Points!$A:$A,row()-2))} -> 104 | BR9: {=IF(BC9="","",INDEX(Points!$A:$A,row()-2))} -> 104 | BS9: {=IF(BD9="","",INDEX(Points!$A:$A,row()-2))} -> 104 | BT9: {=IF(BE9="","",INDEX(Points!$A:$A,row()-2))} -> 104 | BU9: {=IF(BF9="","",INDEX(Points!$A:$A,row()-2))} | BV9: {=IF(BG9="","",INDEX(Points!$A:$A,row()-2))} | ... CC9: {=IF(BN9="","",INDEX(Points!$A:$A,row()-2))} -> 104 | CD9: =index($AZ$3:$BF$100,Mod(row()-3,$CD$1)+1,int((row()-3)/$CD$1)+1) | CE9: =IFERROR(__xludf.DUMMYFUNCTION("""COMPUTED_VALUE"""),"Nightmare") -> Nightmare | CF9: =if(CE9="","",sum(CG9:CU9)) -> 763 | CG9: =if($CE9="","",sumif(AZ:AZ,$CE9,BO:BO)) -> 0 | CH9: =if($CE9="","",sumif(BA:BA,$CE9,BP:BP)) -> 0 | CI9: =if($CE9="","",sumif(BB:BB,$CE9,BQ:BQ)) -> 106 | CJ9: =if($CE9="","",sumif(BC:BC,$CE9,BR:BR)) -> 0 | CK9: =if($CE9="","",sumif(BD:BD,$CE9,BS:BS)) -> 106 | CL9: =if($CE9="","",sumif(BE:BE,$CE9,BT:BT)) -> 113 | CM9: =if($CE9="","",sumif(BF:BF,$CE9,BU:BU)) -> 0 | CN9: =if($CE9="","",sumif(BG:BG,$CE9,BV:BV)) -> 0 | CO9: =if($CE9="","",sumif(BH:BH,$CE9,BW:BW)) -> 0 | CP9: =if($CE9="","",sumif(BI:BI,$CE9,BX:BX)) -> 0 | CQ9: =if($CE9="","",sumif(BJ:BJ,$CE9,BY:BY)) -> 106 | CR9: =if($CE9="","",sumif(BK:BK,$CE9,BZ:BZ)) -> 0 | CS9: =if($CE9="","",sumif(BL:BL,$CE9,CA:CA)) -> 106 | CT9: =if($CE9="","",sumif(BM:BM,$CE9,CB:CB)) -> 113 | CU9: =if($CE9="","",sumif(BN:BN,$CE9,CC:CC)) -> 113
D10: Dada 24.536 | E10: Gutterbutter 17.165 | F10: Jesko 36.171 | G10: Retep 10.070 | L10: Dada 24.536 | M10: Gutterbutter 17.165 | N10: Jesko 36.171 | O10: Retep 10.070 | P10: Retep 10.070 | R10: =if(T10="","",rank(T10,T:T,false)) -> 8 | S10: HeisRisen | T10: 534 | U10: 0 | V10: 0 | W10: 108 | X10: 0 | Y10: 0 | Z10: 106 | AA10: 0 | AB10: 0 | AC10: 0 | AD10: 0 | AE10: 108 | AF10: 0 | AG10: 0 | AH10: 106 | AI10: 106 | AK10: =iferror(find(" ",B10) ,"") | AL10: =iferror(find(" ",C10) ,"") | AM10: =iferror(find(" ",D10) ,"") -> 5 | AN10: =iferror(find(" ",E10) ,"") -> 13 | AO10: =iferror(find(" ",F10) ,"") -> 6 | AP10: =iferror(find(" ",G10) ,"") -> 6 | AQ10: =iferror(find(" ",H10) ,"") | AR10: =iferror(find(" ",I10) ,"") | ... AY10: =iferror(find(" ",P10) ,"") -> 6 | AZ10: =if(and(len(B10)>0,AK10=""),B10,iferror(left(B10, AK10-1),"")) | BA10: =if(and(len(C10)>0,AL10=""),C10,iferror(left(C10, AL10-1),"")) | BB10: =if(and(len(D10)>0,AM10=""),D10,iferror(left(D10, AM10-1),"")) -> Dada | BC10: =if(and(len(E10)>0,AN10=""),E10,iferror(left(E10, AN10-1),"")) -> Gutterbutter | BD10: =if(and(len(F10)>0,AO10=""),F10,iferror(left(F10, AO10-1),"")) -> Jesko | BE10: =if(and(len(G10)>0,AP10=""),G10,iferror(left(G10, AP10-1),"")) -> Retep | BF10: =if(and(len(H10)>0,AQ10=""),H10,iferror(left(H10, AQ10-1),"")) | BG10: =if(and(len(I10)>0,AR10=""),I10,iferror(left(I10, AR10-1),"")) | ... BN10: =if(and(len(P10)>0,AY10=""),P10,iferror(left(P10, AY10-1),"")) -> Retep | BO10: {=IF(AZ10="","",INDEX(Points!$A:$A,row()-2))} | BP10: {=IF(BA10="","",INDEX(Points!$A:$A,row()-2))} | BQ10: {=IF(BB10="","",INDEX(Points!$A:$A,row()-2))} -> 102 | BR10: {=IF(BC10="","",INDEX(Points!$A:$A,row()-2))} -> 102 | BS10: {=IF(BD10="","",INDEX(Points!$A:$A,row()-2))} -> 102 | BT10: {=IF(BE10="","",INDEX(Points!$A:$A,row()-2))} -> 102 | BU10: {=IF(BF10="","",INDEX(Points!$A:$A,row()-2))} | BV10: {=IF(BG10="","",INDEX(Points!$A:$A,row()-2))} | ... CC10: {=IF(BN10="","",INDEX(Points!$A:$A,row()-2))} -> 102 | CD10: =index($AZ$3:$BF$100,Mod(row()-3,$CD$1)+1,int((row()-3)/$CD$1)+1) | CE10: =IFERROR(__xludf.DUMMYFUNCTION("""COMPUTED_VALUE"""),"Retep") -> Retep | CF10: =if(CE10="","",sum(CG10:CU10)) -> 730 | CG10: =if($CE10="","",sumif(AZ:AZ,$CE10,BO:BO)) -> 0 | CH10: =if($CE10="","",sumif(BA:BA,$CE10,BP:BP)) -> 0 | CI10: =if($CE10="","",sumif(BB:BB,$CE10,BQ:BQ)) -> 104 | CJ10: =if($CE10="","",sumif(BC:BC,$CE10,BR:BR)) -> 108 | CK10: =if($CE10="","",sumif(BD:BD,$CE10,BS:BS)) -> 0 | CL10: =if($CE10="","",sumif(BE:BE,$CE10,BT:BT)) -> 102 | CM10: =if($CE10="","",sumif(BF:BF,$CE10,BU:BU)) -> 0 | CN10: =if($CE10="","",sumif(BG:BG,$CE10,BV:BV)) -> 0 | CO10: =if($CE10="","",sumif(BH:BH,$CE10,BW:BW)) -> 0 | CP10: =if($CE10="","",sumif(BI:BI,$CE10,BX:BX)) -> 0 | CQ10: =if($CE10="","",sumif(BJ:BJ,$CE10,BY:BY)) -> 104 | CR10: =if($CE10="","",sumif(BK:BK,$CE10,BZ:BZ)) -> 108 | CS10: =if($CE10="","",sumif(BL:BL,$CE10,CA:CA)) -> 0 | CT10: =if($CE10="","",sumif(BM:BM,$CE10,CB:CB)) -> 102 | CU10: =if($CE10="","",sumif(BN:BN,$CE10,CC:CC)) -> 102
D11: TechG 26.350 | E11: Jesko 17.535 | G11: GotGoing 10.145 | L11: TechG 26.350 | M11: Jesko 17.535 | O11: GotGoing 10.145 | P11: GotGoing 10.145 | R11: =if(T11="","",rank(T11,T:T,false)) -> 9 | S11: Fishy | T11: 520 | U11: 0 | V11: 0 | W11: 0 | X11: 0 | Y11: 110 | Z11: 100 | AA11: 0 | AB11: 0 | AC11: 0 | AD11: 0 | AE11: 0 | AF11: 0 | AG11: 110 | AH11: 100 | AI11: 100 | AK11: =iferror(find(" ",B11) ,"") | AL11: =iferror(find(" ",C11) ,"") | AM11: =iferror(find(" ",D11) ,"") -> 6 | AN11: =iferror(find(" ",E11) ,"") -> 6 | AO11: =iferror(find(" ",F11) ,"") | AP11: =iferror(find(" ",G11) ,"") -> 9 | AQ11: =iferror(find(" ",H11) ,"") | AR11: =iferror(find(" ",I11) ,"") | ... AY11: =iferror(find(" ",P11) ,"") -> 9 | AZ11: =if(and(len(B11)>0,AK11=""),B11,iferror(left(B11, AK11-1),"")) | BA11: =if(and(len(C11)>0,AL11=""),C11,iferror(left(C11, AL11-1),"")) | BB11: =if(and(len(D11)>0,AM11=""),D11,iferror(left(D11, AM11-1),"")) -> TechG | BC11: =if(and(len(E11)>0,AN11=""),E11,iferror(left(E11, AN11-1),"")) -> Jesko | BD11: =if(and(len(F11)>0,AO11=""),F11,iferror(left(F11, AO11-1),"")) | BE11: =if(and(len(G11)>0,AP11=""),G11,iferror(left(G11, AP11-1),"")) -> GotGoing | BF11: =if(and(len(H11)>0,AQ11=""),H11,iferror(left(H11, AQ11-1),"")) | BG11: =if(and(len(I11)>0,AR11=""),I11,iferror(left(I11, AR11-1),"")) | ... BN11: =if(and(len(P11)>0,AY11=""),P11,iferror(left(P11, AY11-1),"")) -> GotGoing | BO11: {=IF(AZ11="","",INDEX(Points!$A:$A,row()-2))} | BP11: {=IF(BA11="","",INDEX(Points!$A:$A,row()-2))} | BQ11: {=IF(BB11="","",INDEX(Points!$A:$A,row()-2))} -> 101 | BR11: {=IF(BC11="","",INDEX(Points!$A:$A,row()-2))} -> 101 | BS11: {=IF(BD11="","",INDEX(Points!$A:$A,row()-2))} | BT11: {=IF(BE11="","",INDEX(Points!$A:$A,row()-2))} -> 101 | BU11: {=IF(BF11="","",INDEX(Points!$A:$A,row()-2))} | BV11: {=IF(BG11="","",INDEX(Points!$A:$A,row()-2))} | ... CC11: {=IF(BN11="","",INDEX(Points!$A:$A,row()-2))} -> 101 | CD11: =index($AZ$3:$BF$100,Mod(row()-3,$CD$1)+1,int((row()-3)/$CD$1)+1) | CE11: =IFERROR(__xludf.DUMMYFUNCTION("""COMPUTED_VALUE"""),"Dada") -> Dada | CF11: =if(CE11="","",sum(CG11:CU11)) -> 204 | CG11: =if($CE11="","",sumif(AZ:AZ,$CE11,BO:BO)) -> 0 | CH11: =if($CE11="","",sumif(BA:BA,$CE11,BP:BP)) -> 0 | CI11: =if($CE11="","",sumif(BB:BB,$CE11,BQ:BQ)) -> 102 | CJ11: =if($CE11="","",sumif(BC:BC,$CE11,BR:BR)) -> 0 | CK11: =if($CE11="","",sumif(BD:BD,$CE11,BS:BS)) -> 0 | CL11: =if($CE11="","",sumif(BE:BE,$CE11,BT:BT)) -> 0 | CM11: =if($CE11="","",sumif(BF:BF,$CE11,BU:BU)) -> 0 | CN11: =if($CE11="","",sumif(BG:BG,$CE11,BV:BV)) -> 0 | CO11: =if($CE11="","",sumif(BH:BH,$CE11,BW:BW)) -> 0 | CP11: =if($CE11="","",sumif(BI:BI,$CE11,BX:BX)) -> 0 | CQ11: =if($CE11="","",sumif(BJ:BJ,$CE11,BY:BY)) -> 102 | CR11: =if($CE11="","",sumif(BK:BK,$CE11,BZ:BZ)) -> 0 | CS11: =if($CE11="","",sumif(BL:BL,$CE11,CA:CA)) -> 0 | CT11: =if($CE11="","",sumif(BM:BM,$CE11,CB:CB)) -> 0 | CU11: =if($CE11="","",sumif(BN:BN,$CE11,CC:CC)) -> 0
D12: Romy 28.383 | G12: Fishy 10.152 | L12: Romy 28.383 | O12: Fishy 10.152 | P12: Fishy 10.152 | R12: =if(T12="","",rank(T12,T:T,false)) -> 10 | S12: Vision | T12: 511 | U12: 0 | V12: 0 | W12: 0 | X12: 110 | Y12: 0 | Z12: 97 | AA12: 0 | AB12: 0 | AC12: 0 | AD12: 0 | AE12: 0 | AF12: 110 | AG12: 0 | AH12: 97 | AI12: 97 | AK12: =iferror(find(" ",B12) ,"") | AL12: =iferror(find(" ",C12) ,"") | AM12: =iferror(find(" ",D12) ,"") -> 5 | AN12: =iferror(find(" ",E12) ,"") | AO12: =iferror(find(" ",F12) ,"") | AP12: =iferror(find(" ",G12) ,"") -> 6 | AQ12: =iferror(find(" ",H12) ,"") | AR12: =iferror(find(" ",I12) ,"") | ... AY12: =iferror(find(" ",P12) ,"") -> 6 | AZ12: =if(and(len(B12)>0,AK12=""),B12,iferror(left(B12, AK12-1),"")) | BA12: =if(and(len(C12)>0,AL12=""),C12,iferror(left(C12, AL12-1),"")) | BB12: =if(and(len(D12)>0,AM12=""),D12,iferror(left(D12, AM12-1),"")) -> Romy | BC12: =if(and(len(E12)>0,AN12=""),E12,iferror(left(E12, AN12-1),"")) | BD12: =if(and(len(F12)>0,AO12=""),F12,iferror(left(F12, AO12-1),"")) | BE12: =if(and(len(G12)>0,AP12=""),G12,iferror(left(G12, AP12-1),"")) -> Fishy | BF12: =if(and(len(H12)>0,AQ12=""),H12,iferror(left(H12, AQ12-1),"")) | BG12: =if(and(len(I12)>0,AR12=""),I12,iferror(left(I12, AR12-1),"")) | ... BN12: =if(and(len(P12)>0,AY12=""),P12,iferror(left(P12, AY12-1),"")) -> Fishy | BO12: {=IF(AZ12="","",INDEX(Points!$A:$A,row()-2))} | BP12: {=IF(BA12="","",INDEX(Points!$A:$A,row()-2))} | BQ12: {=IF(BB12="","",INDEX(Points!$A:$A,row()-2))} -> 100 | BR12: {=IF(BC12="","",INDEX(Points!$A:$A,row()-2))} | BS12: {=IF(BD12="","",INDEX(Points!$A:$A,row()-2))} | BT12: {=IF(BE12="","",INDEX(Points!$A:$A,row()-2))} -> 100 | BU12: {=IF(BF12="","",INDEX(Points!$A:$A,row()-2))} | BV12: {=IF(BG12="","",INDEX(Points!$A:$A,row()-2))} | ... CC12: {=IF(BN12="","",INDEX(Points!$A:$A,row()-2))} -> 100 | CD12: =index($AZ$3:$BF$100,Mod(row()-3,$CD$1)+1,int((row()-3)/$CD$1)+1) | CE12: =IFERROR(__xludf.DUMMYFUNCTION("""COMPUTED_VALUE"""),"TechG") -> TechG | CF12: =if(CE12="","",sum(CG12:CU12)) -> 202 | CG12: =if($CE12="","",sumif(AZ:AZ,$CE12,BO:BO)) -> 0 | CH12: =if($CE12="","",sumif(BA:BA,$CE12,BP:BP)) -> 0 | CI12: =if($CE12="","",sumif(BB:BB,$CE12,BQ:BQ)) -> 101 | CJ12: =if($CE12="","",sumif(BC:BC,$CE12,BR:BR)) -> 0 | CK12: =if($CE12="","",sumif(BD:BD,$CE12,BS:BS)) -> 0 | CL12: =if($CE12="","",sumif(BE:BE,$CE12,BT:BT)) -> 0 | CM12: =if($CE12="","",sumif(BF:BF,$CE12,BU:BU)) -> 0 | CN12: =if($CE12="","",sumif(BG:BG,$CE12,BV:BV)) -> 0 | CO12: =if($CE12="","",sumif(BH:BH,$CE12,BW:BW)) -> 0 | CP12: =if($CE12="","",sumif(BI:BI,$CE12,BX:BX)) -> 0 | CQ12: =if($CE12="","",sumif(BJ:BJ,$CE12,BY:BY)) -> 101 | CR12: =if($CE12="","",sumif(BK:BK,$CE12,BZ:BZ)) -> 0 | CS12: =if($CE12="","",sumif(BL:BL,$CE12,CA:CA)) -> 0 | CT12: =if($CE12="","",sumif(BM:BM,$CE12,CB:CB)) -> 0 | CU12: =if($CE12="","",sumif(BN:BN,$CE12,CC:CC)) -> 0
G13: Ragdoll 10.172 | O13: Ragdoll 10.172 | P13: Ragdoll 10.172 | R13: =if(T13="","",rank(T13,T:T,false)) -> 11 | S13: Leif | T13: 464 | U13: 0 | V13: 0 | W13: 113 | X13: 0 | Y13: 119 | Z13: 0 | AA13: 0 | AB13: 0 | AC13: 0 | AD13: 0 | AE13: 113 | AF13: 0 | AG13: 119 | AH13: 0 | AI13: 0 | AK13: =iferror(find(" ",B13) ,"") | AL13: =iferror(find(" ",C13) ,"") | AM13: =iferror(find(" ",D13) ,"") | AN13: =iferror(find(" ",E13) ,"") | AO13: =iferror(find(" ",F13) ,"") | AP13: =iferror(find(" ",G13) ,"") -> 8 | AQ13: =iferror(find(" ",H13) ,"") | AR13: =iferror(find(" ",I13) ,"") | ... AY13: =iferror(find(" ",P13) ,"") -> 8 | AZ13: =if(and(len(B13)>0,AK13=""),B13,iferror(left(B13, AK13-1),"")) | BA13: =if(and(len(C13)>0,AL13=""),C13,iferror(left(C13, AL13-1),"")) | BB13: =if(and(len(D13)>0,AM13=""),D13,iferror(left(D13, AM13-1),"")) | BC13: =if(and(len(E13)>0,AN13=""),E13,iferror(left(E13, AN13-1),"")) | BD13: =if(and(len(F13)>0,AO13=""),F13,iferror(left(F13, AO13-1),"")) | BE13: =if(and(len(G13)>0,AP13=""),G13,iferror(left(G13, AP13-1),"")) -> Ragdoll | BF13: =if(and(len(H13)>0,AQ13=""),H13,iferror(left(H13, AQ13-1),"")) | BG13: =if(and(len(I13)>0,AR13=""),I13,iferror(left(I13, AR13-1),"")) | ... BN13: =if(and(len(P13)>0,AY13=""),P13,iferror(left(P13, AY13-1),"")) -> Ragdoll | BO13: {=IF(AZ13="","",INDEX(Points!$A:$A,row()-2))} | BP13: {=IF(BA13="","",INDEX(Points!$A:$A,row()-2))} | BQ13: {=IF(BB13="","",INDEX(Points!$A:$A,row()-2))} | BR13: {=IF(BC13="","",INDEX(Points!$A:$A,row()-2))} | BS13: {=IF(BD13="","",INDEX(Points!$A:$A,row()-2))} | BT13: {=IF(BE13="","",INDEX(Points!$A:$A,row()-2))} -> 99 | BU13: {=IF(BF13="","",INDEX(Points!$A:$A,row()-2))} | BV13: {=IF(BG13="","",INDEX(Points!$A:$A,row()-2))} | ... CC13: {=IF(BN13="","",INDEX(Points!$A:$A,row()-2))} -> 99 | CD13: =index($AZ$3:$BF$100,Mod(row()-3,$CD$1)+1,int((row()-3)/$CD$1)+1) | CE13: =IFERROR(__xludf.DUMMYFUNCTION("""COMPUTED_VALUE"""),"Romy") -> Romy | CF13: =if(CE13="","",sum(CG13:CU13)) -> 200 | CG13: =if($CE13="","",sumif(AZ:AZ,$CE13,BO:BO)) -> 0 | CH13: =if($CE13="","",sumif(BA:BA,$CE13,BP:BP)) -> 0 | CI13: =if($CE13="","",sumif(BB:BB,$CE13,BQ:BQ)) -> 100 | CJ13: =if($CE13="","",sumif(BC:BC,$CE13,BR:BR)) -> 0 | CK13: =if($CE13="","",sumif(BD:BD,$CE13,BS:BS)) -> 0 | CL13: =if($CE13="","",sumif(BE:BE,$CE13,BT:BT)) -> 0 | CM13: =if($CE13="","",sumif(BF:BF,$CE13,BU:BU)) -> 0 | CN13: =if($CE13="","",sumif(BG:BG,$CE13,BV:BV)) -> 0 | CO13: =if($CE13="","",sumif(BH:BH,$CE13,BW:BW)) -> 0 | CP13: =if($CE13="","",sumif(BI:BI,$CE13,BX:BX)) -> 0 | CQ13: =if($CE13="","",sumif(BJ:BJ,$CE13,BY:BY)) -> 100 | CR13: =if($CE13="","",sumif(BK:BK,$CE13,BZ:BZ)) -> 0 | CS13: =if($CE13="","",sumif(BL:BL,$CE13,CA:CA)) -> 0 | CT13: =if($CE13="","",sumif(BM:BM,$CE13,CB:CB)) -> 0 | CU13: =if($CE13="","",sumif(BN:BN,$CE13,CC:CC)) -> 0
G14: Folo 10.520 | O14: Folo 10.520 | P14: Folo 10.520 | R14: =if(T14="","",rank(T14,T:T,false)) -> 12 | S14: Boodles | T14: 440 | U14: 0 | V14: 0 | W14: 116 | X14: 104 | Y14: 0 | Z14: 0 | AA14: 0 | AB14: 0 | AC14: 0 | AD14: 0 | AE14: 116 | AF14: 104 | AG14: 0 | AH14: 0 | AI14: 0 | AK14: =iferror(find(" ",B14) ,"") | AL14: =iferror(find(" ",C14) ,"") | AM14: =iferror(find(" ",D14) ,"") | AN14: =iferror(find(" ",E14) ,"") | AO14: =iferror(find(" ",F14) ,"") | AP14: =iferror(find(" ",G14) ,"") -> 5 | AQ14: =iferror(find(" ",H14) ,"") | AR14: =iferror(find(" ",I14) ,"") | ... AY14: =iferror(find(" ",P14) ,"") -> 5 | AZ14: =if(and(len(B14)>0,AK14=""),B14,iferror(left(B14, AK14-1),"")) | BA14: =if(and(len(C14)>0,AL14=""),C14,iferror(left(C14, AL14-1),"")) | BB14: =if(and(len(D14)>0,AM14=""),D14,iferror(left(D14, AM14-1),"")) | BC14: =if(and(len(E14)>0,AN14=""),E14,iferror(left(E14, AN14-1),"")) | BD14: =if(and(len(F14)>0,AO14=""),F14,iferror(left(F14, AO14-1),"")) | BE14: =if(and(len(G14)>0,AP14=""),G14,iferror(left(G14, AP14-1),"")) -> Folo | BF14: =if(and(len(H14)>0,AQ14=""),H14,iferror(left(H14, AQ14-1),"")) | BG14: =if(and(len(I14)>0,AR14=""),I14,iferror(left(I14, AR14-1),"")) | ... BN14: =if(and(len(P14)>0,AY14=""),P14,iferror(left(P14, AY14-1),"")) -> Folo | BO14: {=IF(AZ14="","",INDEX(Points!$A:$A,row()-2))} | BP14: {=IF(BA14="","",INDEX(Points!$A:$A,row()-2))} | BQ14: {=IF(BB14="","",INDEX(Points!$A:$A,row()-2))} | BR14: {=IF(BC14="","",INDEX(Points!$A:$A,row()-2))} | BS14: {=IF(BD14="","",INDEX(Points!$A:$A,row()-2))} | BT14: {=IF(BE14="","",INDEX(Points!$A:$A,row()-2))} -> 98 | BU14: {=IF(BF14="","",INDEX(Points!$A:$A,row()-2))} | BV14: {=IF(BG14="","",INDEX(Points!$A:$A,row()-2))} | ... CC14: {=IF(BN14="","",INDEX(Points!$A:$A,row()-2))} -> 98 | CD14: =index($AZ$3:$BF$100,Mod(row()-3,$CD$1)+1,int((row()-3)/$CD$1)+1) | CE14: =IFERROR(__xludf.DUMMYFUNCTION("""COMPUTED_VALUE"""),"Ollie") -> Ollie | CF14: =if(CE14="","",sum(CG14:CU14)) -> 238 | CG14: =if($CE14="","",sumif(AZ:AZ,$CE14,BO:BO)) -> 0 | CH14: =if($CE14="","",sumif(BA:BA,$CE14,BP:BP)) -> 0 | CI14: =if($CE14="","",sumif(BB:BB,$CE14,BQ:BQ)) -> 0 | CJ14: =if($CE14="","",sumif(BC:BC,$CE14,BR:BR)) -> 119 | CK14: =if($CE14="","",sumif(BD:BD,$CE14,BS:BS)) -> 0 | CL14: =if($CE14="","",sumif(BE:BE,$CE14,BT:BT)) -> 0 | CM14: =if($CE14="","",sumif(BF:BF,$CE14,BU:BU)) -> 0 | CN14: =if($CE14="","",sumif(BG:BG,$CE14,BV:BV)) -> 0 | CO14: =if($CE14="","",sumif(BH:BH,$CE14,BW:BW)) -> 0 | CP14: =if($CE14="","",sumif(BI:BI,$CE14,BX:BX)) -> 0 | CQ14: =if($CE14="","",sumif(BJ:BJ,$CE14,BY:BY)) -> 0 | CR14: =if($CE14="","",sumif(BK:BK,$CE14,BZ:BZ)) -> 119 | CS14: =if($CE14="","",sumif(BL:BL,$CE14,CA:CA)) -> 0 | CT14: =if($CE14="","",sumif(BM:BM,$CE14,CB:CB)) -> 0 | CU14: =if($CE14="","",sumif(BN:BN,$CE14,CC:CC)) -> 0
G15: Vision 10.563 | O15: Vision 10.563 | P15: Vision 10.563 | R15: =if(T15="","",rank(T15,T:T,false)) -> 13 | S15: DGG | T15: 324 | U15: 0 | V15: 0 | W15: 0 | X15: 0 | Y15: 0 | Z15: 108 | AA15: 0 | AB15: 0 | AC15: 0 | AD15: 0 | AE15: 0 | AF15: 0 | AG15: 0 | AH15: 108 | AI15: 108 | AK15: =iferror(find(" ",B15) ,"") | AL15: =iferror(find(" ",C15) ,"") | AM15: =iferror(find(" ",D15) ,"") | AN15: =iferror(find(" ",E15) ,"") | AO15: =iferror(find(" ",F15) ,"") | AP15: =iferror(find(" ",G15) ,"") -> 7 | AQ15: =iferror(find(" ",H15) ,"") | AR15: =iferror(find(" ",I15) ,"") | ... AY15: =iferror(find(" ",P15) ,"") -> 7 | AZ15: =if(and(len(B15)>0,AK15=""),B15,iferror(left(B15, AK15-1),"")) | BA15: =if(and(len(C15)>0,AL15=""),C15,iferror(left(C15, AL15-1),"")) | BB15: =if(and(len(D15)>0,AM15=""),D15,iferror(left(D15, AM15-1),"")) | BC15: =if(and(len(E15)>0,AN15=""),E15,iferror(left(E15, AN15-1),"")) | BD15: =if(and(len(F15)>0,AO15=""),F15,iferror(left(F15, AO15-1),"")) | BE15: =if(and(len(G15)>0,AP15=""),G15,iferror(left(G15, AP15-1),"")) -> Vision | BF15: =if(and(len(H15)>0,AQ15=""),H15,iferror(left(H15, AQ15-1),"")) | BG15: =if(and(len(I15)>0,AR15=""),I15,iferror(left(I15, AR15-1),"")) | ... BN15: =if(and(len(P15)>0,AY15=""),P15,iferror(left(P15, AY15-1),"")) -> Vision | BO15: {=IF(AZ15="","",INDEX(Points!$A:$A,row()-2))} | BP15: {=IF(BA15="","",INDEX(Points!$A:$A,row()-2))} | BQ15: {=IF(BB15="","",INDEX(Points!$A:$A,row()-2))} | BR15: {=IF(BC15="","",INDEX(Points!$A:$A,row()-2))} | BS15: {=IF(BD15="","",INDEX(Points!$A:$A,row()-2))} | BT15: {=IF(BE15="","",INDEX(Points!$A:$A,row()-2))} -> 97 | BU15: {=IF(BF15="","",INDEX(Points!$A:$A,row()-2))} | BV15: {=IF(BG15="","",INDEX(Points!$A:$A,row()-2))} | ... CC15: {=IF(BN15="","",INDEX(Points!$A:$A,row()-2))} -> 97 | CD15: =index($AZ$3:$BF$100,Mod(row()-3,$CD$1)+1,int((row()-3)/$CD$1)+1) | CE15: =IFERROR(__xludf.DUMMYFUNCTION("""COMPUTED_VALUE"""),"DropX") -> DropX | CF15: =if(CE15="","",sum(CG15:CU15)) -> 232 | CG15: =if($CE15="","",sumif(AZ:AZ,$CE15,BO:BO)) -> 0 | CH15: =if($CE15="","",sumif(BA:BA,$CE15,BP:BP)) -> 0 | CI15: =if($CE15="","",sumif(BB:BB,$CE15,BQ:BQ)) -> 0 | CJ15: =if($CE15="","",sumif(BC:BC,$CE15,BR:BR)) -> 116 | CK15: =if($CE15="","",sumif(BD:BD,$CE15,BS:BS)) -> 0 | CL15: =if($CE15="","",sumif(BE:BE,$CE15,BT:BT)) -> 0 | CM15: =if($CE15="","",sumif(BF:BF,$CE15,BU:BU)) -> 0 | CN15: =if($CE15="","",sumif(BG:BG,$CE15,BV:BV)) -> 0 | CO15: =if($CE15="","",sumif(BH:BH,$CE15,BW:BW)) -> 0 | CP15: =if($CE15="","",sumif(BI:BI,$CE15,BX:BX)) -> 0 | CQ15: =if($CE15="","",sumif(BJ:BJ,$CE15,BY:BY)) -> 0 | CR15: =if($CE15="","",sumif(BK:BK,$CE15,BZ:BZ)) -> 116 | CS15: =if($CE15="","",sumif(BL:BL,$CE15,CA:CA)) -> 0 | CT15: =if($CE15="","",sumif(BM:BM,$CE15,CB:CB)) -> 0 | CU15: =if($CE15="","",sumif(BN:BN,$CE15,CC:CC)) -> 0
R16: =if(T16="","",rank(T16,T:T,false)) -> 14 | S16: Ragdoll | T16: 297 | U16: 0 | V16: 0 | W16: 0 | X16: 0 | Y16: 0 | Z16: 99 | AA16: 0 | AB16: 0 | AC16: 0 | AD16: 0 | AE16: 0 | AF16: 0 | AG16: 0 | AH16: 99 | AI16: 99 | AK16: =iferror(find(" ",B16) ,"") | AL16: =iferror(find(" ",C16) ,"") | AM16: =iferror(find(" ",D16) ,"") | AN16: =iferror(find(" ",E16) ,"") | AO16: =iferror(find(" ",F16) ,"") | AP16: =iferror(find(" ",G16) ,"") | AQ16: =iferror(find(" ",H16) ,"") | AR16: =iferror(find(" ",I16) ,"") | ... AY16: =iferror(find(" ",P16) ,"") | AZ16: =if(and(len(B16)>0,AK16=""),B16,iferror(left(B16, AK16-1),"")) | BA16: =if(and(len(C16)>0,AL16=""),C16,iferror(left(C16, AL16-1),"")) | BB16: =if(and(len(D16)>0,AM16=""),D16,iferror(left(D16, AM16-1),"")) | BC16: =if(and(len(E16)>0,AN16=""),E16,iferror(left(E16, AN16-1),"")) | BD16: =if(and(len(F16)>0,AO16=""),F16,iferror(left(F16, AO16-1),"")) | BE16: =if(and(len(G16)>0,AP16=""),G16,iferror(left(G16, AP16-1),"")) | BF16: =if(and(len(H16)>0,AQ16=""),H16,iferror(left(H16, AQ16-1),"")) | BG16: =if(and(len(I16)>0,AR16=""),I16,iferror(left(I16, AR16-1),"")) | ... BN16: =if(and(len(P16)>0,AY16=""),P16,iferror(left(P16, AY16-1),"")) | BO16: {=IF(AZ16="","",INDEX(Points!$A:$A,row()-2))} | BP16: {=IF(BA16="","",INDEX(Points!$A:$A,row()-2))} | BQ16: {=IF(BB16="","",INDEX(Points!$A:$A,row()-2))} | BR16: {=IF(BC16="","",INDEX(Points!$A:$A,row()-2))} | BS16: {=IF(BD16="","",INDEX(Points!$A:$A,row()-2))} | BT16: {=IF(BE16="","",INDEX(Points!$A:$A,row()-2))} | BU16: {=IF(BF16="","",INDEX(Points!$A:$A,row()-2))} | BV16: {=IF(BG16="","",INDEX(Points!$A:$A,row()-2))} | ... CC16: {=IF(BN16="","",INDEX(Points!$A:$A,row()-2))} | CD16: =index($AZ$3:$BF$100,Mod(row()-3,$CD$1)+1,int((row()-3)/$CD$1)+1) | CE16: =IFERROR(__xludf.DUMMYFUNCTION("""COMPUTED_VALUE"""),"Vision") -> Vision | CF16: =if(CE16="","",sum(CG16:CU16)) -> 511 | CG16: =if($CE16="","",sumif(AZ:AZ,$CE16,BO:BO)) -> 0 | CH16: =if($CE16="","",sumif(BA:BA,$CE16,BP:BP)) -> 0 | CI16: =if($CE16="","",sumif(BB:BB,$CE16,BQ:BQ)) -> 0 | CJ16: =if($CE16="","",sumif(BC:BC,$CE16,BR:BR)) -> 110 | CK16: =if($CE16="","",sumif(BD:BD,$CE16,BS:BS)) -> 0 | CL16: =if($CE16="","",sumif(BE:BE,$CE16,BT:BT)) -> 97 | CM16: =if($CE16="","",sumif(BF:BF,$CE16,BU:BU)) -> 0 | CN16: =if($CE16="","",sumif(BG:BG,$CE16,BV:BV)) -> 0 | CO16: =if($CE16="","",sumif(BH:BH,$CE16,BW:BW)) -> 0 | CP16: =if($CE16="","",sumif(BI:BI,$CE16,BX:BX)) -> 0 | CQ16: =if($CE16="","",sumif(BJ:BJ,$CE16,BY:BY)) -> 0 | CR16: =if($CE16="","",sumif(BK:BK,$CE16,BZ:BZ)) -> 110 | CS16: =if($CE16="","",sumif(BL:BL,$CE16,CA:CA)) -> 0 | CT16: =if($CE16="","",sumif(BM:BM,$CE16,CB:CB)) -> 97 | CU16: =if($CE16="","",sumif(BN:BN,$CE16,CC:CC)) -> 97
R17: =if(T17="","",rank(T17,T:T,false)) -> 15 | S17: Folo | T17: 294 | U17: 0 | V17: 0 | W17: 0 | X17: 0 | Y17: 0 | Z17: 98 | AA17: 0 | AB17: 0 | AC17: 0 | AD17: 0 | AE17: 0 | AF17: 0 | AG17: 0 | AH17: 98 | AI17: 98 | AK17: =iferror(find(" ",B17) ,"") | AL17: =iferror(find(" ",C17) ,"") | AM17: =iferror(find(" ",D17) ,"") | AN17: =iferror(find(" ",E17) ,"") | AO17: =iferror(find(" ",F17) ,"") | AP17: =iferror(find(" ",G17) ,"") | AQ17: =iferror(find(" ",H17) ,"") | AR17: =iferror(find(" ",I17) ,"") | ... AY17: =iferror(find(" ",P17) ,"") | AZ17: =if(and(len(B17)>0,AK17=""),B17,iferror(left(B17, AK17-1),"")) | BA17: =if(and(len(C17)>0,AL17=""),C17,iferror(left(C17, AL17-1),"")) | BB17: =if(and(len(D17)>0,AM17=""),D17,iferror(left(D17, AM17-1),"")) | BC17: =if(and(len(E17)>0,AN17=""),E17,iferror(left(E17, AN17-1),"")) | BD17: =if(and(len(F17)>0,AO17=""),F17,iferror(left(F17, AO17-1),"")) | BE17: =if(and(len(G17)>0,AP17=""),G17,iferror(left(G17, AP17-1),"")) | BF17: =if(and(len(H17)>0,AQ17=""),H17,iferror(left(H17, AQ17-1),"")) | BG17: =if(and(len(I17)>0,AR17=""),I17,iferror(left(I17, AR17-1),"")) | ... BN17: =if(and(len(P17)>0,AY17=""),P17,iferror(left(P17, AY17-1),"")) | BO17: {=IF(AZ17="","",INDEX(Points!$A:$A,row()-2))} | BP17: {=IF(BA17="","",INDEX(Points!$A:$A,row()-2))} | BQ17: {=IF(BB17="","",INDEX(Points!$A:$A,row()-2))} | BR17: {=IF(BC17="","",INDEX(Points!$A:$A,row()-2))} | BS17: {=IF(BD17="","",INDEX(Points!$A:$A,row()-2))} | BT17: {=IF(BE17="","",INDEX(Points!$A:$A,row()-2))} | BU17: {=IF(BF17="","",INDEX(Points!$A:$A,row()-2))} | BV17: {=IF(BG17="","",INDEX(Points!$A:$A,row()-2))} | ... CC17: {=IF(BN17="","",INDEX(Points!$A:$A,row()-2))} | CD17: =index($AZ$3:$BF$100,Mod(row()-3,$CD$1)+1,int((row()-3)/$CD$1)+1) | CE17: =IFERROR(__xludf.DUMMYFUNCTION("""COMPUTED_VALUE"""),"Gutterbutter") -> Gutterbutter | CF17: =if(CE17="","",sum(CG17:CU17)) -> 724 | CG17: =if($CE17="","",sumif(AZ:AZ,$CE17,BO:BO)) -> 0 | CH17: =if($CE17="","",sumif(BA:BA,$CE17,BP:BP)) -> 0 | CI17: =if($CE17="","",sumif(BB:BB,$CE17,BQ:BQ)) -> 0 | CJ17: =if($CE17="","",sumif(BC:BC,$CE17,BR:BR)) -> 102 | CK17: =if($CE17="","",sumif(BD:BD,$CE17,BS:BS)) -> 104 | CL17: =if($CE17="","",sumif(BE:BE,$CE17,BT:BT)) -> 104 | CM17: =if($CE17="","",sumif(BF:BF,$CE17,BU:BU)) -> 0 | CN17: =if($CE17="","",sumif(BG:BG,$CE17,BV:BV)) -> 0 | CO17: =if($CE17="","",sumif(BH:BH,$CE17,BW:BW)) -> 0 | CP17: =if($CE17="","",sumif(BI:BI,$CE17,BX:BX)) -> 0 | CQ17: =if($CE17="","",sumif(BJ:BJ,$CE17,BY:BY)) -> 0 | CR17: =if($CE17="","",sumif(BK:BK,$CE17,BZ:BZ)) -> 102 | CS17: =if($CE17="","",sumif(BL:BL,$CE17,CA:CA)) -> 104 | CT17: =if($CE17="","",sumif(BM:BM,$CE17,CB:CB)) -> 104 | CU17: =if($CE17="","",sumif(BN:BN,$CE17,CC:CC)) -> 104
R18: =if(T18="","",rank(T18,T:T,false)) -> 16 | S18: Ollie | T18: 238 | U18: 0 | V18: 0 | W18: 0 | X18: 119 | Y18: 0 | Z18: 0 | AA18: 0 | AB18: 0 | AC18: 0 | AD18: 0 | AE18: 0 | AF18: 119 | AG18: 0 | AH18: 0 | AI18: 0 | AK18: =iferror(find(" ",B18) ,"") | AL18: =iferror(find(" ",C18) ,"") | AM18: =iferror(find(" ",D18) ,"") | AN18: =iferror(find(" ",E18) ,"") | AO18: =iferror(find(" ",F18) ,"") | AP18: =iferror(find(" ",G18) ,"") | AQ18: =iferror(find(" ",H18) ,"") | AR18: =iferror(find(" ",I18) ,"") | ... AY18: =iferror(find(" ",P18) ,"") | AZ18: =if(and(len(B18)>0,AK18=""),B18,iferror(left(B18, AK18-1),"")) | BA18: =if(and(len(C18)>0,AL18=""),C18,iferror(left(C18, AL18-1),"")) | BB18: =if(and(len(D18)>0,AM18=""),D18,iferror(left(D18, AM18-1),"")) | BC18: =if(and(len(E18)>0,AN18=""),E18,iferror(left(E18, AN18-1),"")) | BD18: =if(and(len(F18)>0,AO18=""),F18,iferror(left(F18, AO18-1),"")) | BE18: =if(and(len(G18)>0,AP18=""),G18,iferror(left(G18, AP18-1),"")) | BF18: =if(and(len(H18)>0,AQ18=""),H18,iferror(left(H18, AQ18-1),"")) | BG18: =if(and(len(I18)>0,AR18=""),I18,iferror(left(I18, AR18-1),"")) | ... BN18: =if(and(len(P18)>0,AY18=""),P18,iferror(left(P18, AY18-1),"")) | BO18: {=IF(AZ18="","",INDEX(Points!$A:$A,row()-2))} | BP18: {=IF(BA18="","",INDEX(Points!$A:$A,row()-2))} | BQ18: {=IF(BB18="","",INDEX(Points!$A:$A,row()-2))} | BR18: {=IF(BC18="","",INDEX(Points!$A:$A,row()-2))} | BS18: {=IF(BD18="","",INDEX(Points!$A:$A,row()-2))} | BT18: {=IF(BE18="","",INDEX(Points!$A:$A,row()-2))} | BU18: {=IF(BF18="","",INDEX(Points!$A:$A,row()-2))} | BV18: {=IF(BG18="","",INDEX(Points!$A:$A,row()-2))} | ... CC18: {=IF(BN18="","",INDEX(Points!$A:$A,row()-2))} | CD18: =index($AZ$3:$BF$100,Mod(row()-3,$CD$1)+1,int((row()-3)/$CD$1)+1) | CE18: =IFERROR(__xludf.DUMMYFUNCTION("""COMPUTED_VALUE"""),"Jesko") -> Jesko | CF18: =if(CE18="","",sum(CG18:CU18)) -> 763 | CG18: =if($CE18="","",sumif(AZ:AZ,$CE18,BO:BO)) -> 0 | CH18: =if($CE18="","",sumif(BA:BA,$CE18,BP:BP)) -> 0 | CI18: =if($CE18="","",sumif(BB:BB,$CE18,BQ:BQ)) -> 0 | CJ18: =if($CE18="","",sumif(BC:BC,$CE18,BR:BR)) -> 101 | CK18: =if($CE18="","",sumif(BD:BD,$CE18,BS:BS)) -> 102 | CL18: =if($CE18="","",sumif(BE:BE,$CE18,BT:BT)) -> 119 | CM18: =if($CE18="","",sumif(BF:BF,$CE18,BU:BU)) -> 0 | CN18: =if($CE18="","",sumif(BG:BG,$CE18,BV:BV)) -> 0 | CO18: =if($CE18="","",sumif(BH:BH,$CE18,BW:BW)) -> 0 | CP18: =if($CE18="","",sumif(BI:BI,$CE18,BX:BX)) -> 0 | CQ18: =if($CE18="","",sumif(BJ:BJ,$CE18,BY:BY)) -> 0 | CR18: =if($CE18="","",sumif(BK:BK,$CE18,BZ:BZ)) -> 101 | CS18: =if($CE18="","",sumif(BL:BL,$CE18,CA:CA)) -> 102 | CT18: =if($CE18="","",sumif(BM:BM,$CE18,CB:CB)) -> 119 | CU18: =if($CE18="","",sumif(BN:BN,$CE18,CC:CC)) -> 119
R19: =if(T19="","",rank(T19,T:T,false)) -> 17 | S19: DropX | T19: 232 | U19: 0 | V19: 0 | W19: 0 | X19: 116 | Y19: 0 | Z19: 0 | AA19: 0 | AB19: 0 | AC19: 0 | AD19: 0 | AE19: 0 | AF19: 116 | AG19: 0 | AH19: 0 | AI19: 0 | AK19: =iferror(find(" ",B19) ,"") | AL19: =iferror(find(" ",C19) ,"") | AM19: =iferror(find(" ",D19) ,"") | AN19: =iferror(find(" ",E19) ,"") | AO19: =iferror(find(" ",F19) ,"") | AP19: =iferror(find(" ",G19) ,"") | AQ19: =iferror(find(" ",H19) ,"") | AR19: =iferror(find(" ",I19) ,"") | ... AY19: =iferror(find(" ",P19) ,"") | AZ19: =if(and(len(B19)>0,AK19=""),B19,iferror(left(B19, AK19-1),"")) | BA19: =if(and(len(C19)>0,AL19=""),C19,iferror(left(C19, AL19-1),"")) | BB19: =if(and(len(D19)>0,AM19=""),D19,iferror(left(D19, AM19-1),"")) | BC19: =if(and(len(E19)>0,AN19=""),E19,iferror(left(E19, AN19-1),"")) | BD19: =if(and(len(F19)>0,AO19=""),F19,iferror(left(F19, AO19-1),"")) | BE19: =if(and(len(G19)>0,AP19=""),G19,iferror(left(G19, AP19-1),"")) | BF19: =if(and(len(H19)>0,AQ19=""),H19,iferror(left(H19, AQ19-1),"")) | BG19: =if(and(len(I19)>0,AR19=""),I19,iferror(left(I19, AR19-1),"")) | ... BN19: =if(and(len(P19)>0,AY19=""),P19,iferror(left(P19, AY19-1),"")) | BO19: {=IF(AZ19="","",INDEX(Points!$A:$A,row()-2))} | BP19: {=IF(BA19="","",INDEX(Points!$A:$A,row()-2))} | BQ19: {=IF(BB19="","",INDEX(Points!$A:$A,row()-2))} | BR19: {=IF(BC19="","",INDEX(Points!$A:$A,row()-2))} | BS19: {=IF(BD19="","",INDEX(Points!$A:$A,row()-2))} | BT19: {=IF(BE19="","",INDEX(Points!$A:$A,row()-2))} | BU19: {=IF(BF19="","",INDEX(Points!$A:$A,row()-2))} | BV19: {=IF(BG19="","",INDEX(Points!$A:$A,row()-2))} | ... CC19: {=IF(BN19="","",INDEX(Points!$A:$A,row()-2))} | CD19: =index($AZ$3:$BF$100,Mod(row()-3,$CD$1)+1,int((row()-3)/$CD$1)+1) | CE19: =IFERROR(__xludf.DUMMYFUNCTION("""COMPUTED_VALUE"""),"Fishy") -> Fishy | CF19: =if(CE19="","",sum(CG19:CU19)) -> 520 | CG19: =if($CE19="","",sumif(AZ:AZ,$CE19,BO:BO)) -> 0 | CH19: =if($CE19="","",sumif(BA:BA,$CE19,BP:BP)) -> 0 | CI19: =if($CE19="","",sumif(BB:BB,$CE19,BQ:BQ)) -> 0 | CJ19: =if($CE19="","",sumif(BC:BC,$CE19,BR:BR)) -> 0 | CK19: =if($CE19="","",sumif(BD:BD,$CE19,BS:BS)) -> 110 | CL19: =if($CE19="","",sumif(BE:BE,$CE19,BT:BT)) -> 100 | CM19: =if($CE19="","",sumif(BF:BF,$CE19,BU:BU)) -> 0 | CN19: =if($CE19="","",sumif(BG:BG,$CE19,BV:BV)) -> 0 | CO19: =if($CE19="","",sumif(BH:BH,$CE19,BW:BW)) -> 0 | CP19: =if($CE19="","",sumif(BI:BI,$CE19,BX:BX)) -> 0 | CQ19: =if($CE19="","",sumif(BJ:BJ,$CE19,BY:BY)) -> 0 | CR19: =if($CE19="","",sumif(BK:BK,$CE19,BZ:BZ)) -> 0 | CS19: =if($CE19="","",sumif(BL:BL,$CE19,CA:CA)) -> 110 | CT19: =if($CE19="","",sumif(BM:BM,$CE19,CB:CB)) -> 100 | CU19: =if($CE19="","",sumif(BN:BN,$CE19,CC:CC)) -> 100
R20: =if(T20="","",rank(T20,T:T,false)) -> 18 | S20: Dada | T20: 204 | U20: 0 | V20: 0 | W20: 102 | X20: 0 | Y20: 0 | Z20: 0 | AA20: 0 | AB20: 0 | AC20: 0 | AD20: 0 | AE20: 102 | AF20: 0 | AG20: 0 | AH20: 0 | AI20: 0 | AK20: =iferror(find(" ",B20) ,"") | AL20: =iferror(find(" ",C20) ,"") | AM20: =iferror(find(" ",D20) ,"") | AN20: =iferror(find(" ",E20) ,"") | AO20: =iferror(find(" ",F20) ,"") | AP20: =iferror(find(" ",G20) ,"") | AQ20: =iferror(find(" ",H20) ,"") | AR20: =iferror(find(" ",I20) ,"") | ... AY20: =iferror(find(" ",P20) ,"") | AZ20: =if(and(len(B20)>0,AK20=""),B20,iferror(left(B20, AK20-1),"")) | BA20: =if(and(len(C20)>0,AL20=""),C20,iferror(left(C20, AL20-1),"")) | BB20: =if(and(len(D20)>0,AM20=""),D20,iferror(left(D20, AM20-1),"")) | BC20: =if(and(len(E20)>0,AN20=""),E20,iferror(left(E20, AN20-1),"")) | BD20: =if(and(len(F20)>0,AO20=""),F20,iferror(left(F20, AO20-1),"")) | BE20: =if(and(len(G20)>0,AP20=""),G20,iferror(left(G20, AP20-1),"")) | BF20: =if(and(len(H20)>0,AQ20=""),H20,iferror(left(H20, AQ20-1),"")) | BG20: =if(and(len(I20)>0,AR20=""),I20,iferror(left(I20, AR20-1),"")) | ... BN20: =if(and(len(P20)>0,AY20=""),P20,iferror(left(P20, AY20-1),"")) | BO20: {=IF(AZ20="","",INDEX(Points!$A:$A,row()-2))} | BP20: {=IF(BA20="","",INDEX(Points!$A:$A,row()-2))} | BQ20: {=IF(BB20="","",INDEX(Points!$A:$A,row()-2))} | BR20: {=IF(BC20="","",INDEX(Points!$A:$A,row()-2))} | BS20: {=IF(BD20="","",INDEX(Points!$A:$A,row()-2))} | BT20: {=IF(BE20="","",INDEX(Points!$A:$A,row()-2))} | BU20: {=IF(BF20="","",INDEX(Points!$A:$A,row()-2))} | BV20: {=IF(BG20="","",INDEX(Points!$A:$A,row()-2))} | ... CC20: {=IF(BN20="","",INDEX(Points!$A:$A,row()-2))} | CD20: =index($AZ$3:$BF$100,Mod(row()-3,$CD$1)+1,int((row()-3)/$CD$1)+1) | CE20: =IFERROR(__xludf.DUMMYFUNCTION("""COMPUTED_VALUE"""),"DGG") -> DGG | CF20: =if(CE20="","",sum(CG20:CU20)) -> 324 | CG20: =if($CE20="","",sumif(AZ:AZ,$CE20,BO:BO)) -> 0 | CH20: =if($CE20="","",sumif(BA:BA,$CE20,BP:BP)) -> 0 | CI20: =if($CE20="","",sumif(BB:BB,$CE20,BQ:BQ)) -> 0 | CJ20: =if($CE20="","",sumif(BC:BC,$CE20,BR:BR)) -> 0 | CK20: =if($CE20="","",sumif(BD:BD,$CE20,BS:BS)) -> 0 | CL20: =if($CE20="","",sumif(BE:BE,$CE20,BT:BT)) -> 108 | CM20: =if($CE20="","",sumif(BF:BF,$CE20,BU:BU)) -> 0 | CN20: =if($CE20="","",sumif(BG:BG,$CE20,BV:BV)) -> 0 | CO20: =if($CE20="","",sumif(BH:BH,$CE20,BW:BW)) -> 0 | CP20: =if($CE20="","",sumif(BI:BI,$CE20,BX:BX)) -> 0 | CQ20: =if($CE20="","",sumif(BJ:BJ,$CE20,BY:BY)) -> 0 | CR20: =if($CE20="","",sumif(BK:BK,$CE20,BZ:BZ)) -> 0 | CS20: =if($CE20="","",sumif(BL:BL,$CE20,CA:CA)) -> 0 | CT20: =if($CE20="","",sumif(BM:BM,$CE20,CB:CB)) -> 108 | CU20: =if($CE20="","",sumif(BN:BN,$CE20,CC:CC)) -> 108
R21: =if(T21="","",rank(T21,T:T,false)) -> 19 | S21: TechG | T21: 202 | U21: 0 | V21: 0 | W21: 101 | X21: 0 | Y21: 0 | Z21: 0 | AA21: 0 | AB21: 0 | AC21: 0 | AD21: 0 | AE21: 101 | AF21: 0 | AG21: 0 | AH21: 0 | AI21: 0 | AK21: =iferror(find(" ",B21) ,"") | AL21: =iferror(find(" ",C21) ,"") | AM21: =iferror(find(" ",D21) ,"") | AN21: =iferror(find(" ",E21) ,"") | AO21: =iferror(find(" ",F21) ,"") | AP21: =iferror(find(" ",G21) ,"") | AQ21: =iferror(find(" ",H21) ,"") | AR21: =iferror(find(" ",I21) ,"") | ... AY21: =iferror(find(" ",P21) ,"") | AZ21: =if(and(len(B21)>0,AK21=""),B21,iferror(left(B21, AK21-1),"")) | BA21: =if(and(len(C21)>0,AL21=""),C21,iferror(left(C21, AL21-1),"")) | BB21: =if(and(len(D21)>0,AM21=""),D21,iferror(left(D21, AM21-1),"")) | BC21: =if(and(len(E21)>0,AN21=""),E21,iferror(left(E21, AN21-1),"")) | BD21: =if(and(len(F21)>0,AO21=""),F21,iferror(left(F21, AO21-1),"")) | BE21: =if(and(len(G21)>0,AP21=""),G21,iferror(left(G21, AP21-1),"")) | BF21: =if(and(len(H21)>0,AQ21=""),H21,iferror(left(H21, AQ21-1),"")) | BG21: =if(and(len(I21)>0,AR21=""),I21,iferror(left(I21, AR21-1),"")) | ... BN21: =if(and(len(P21)>0,AY21=""),P21,iferror(left(P21, AY21-1),"")) | BO21: {=IF(AZ21="","",INDEX(Points!$A:$A,row()-2))} | BP21: {=IF(BA21="","",INDEX(Points!$A:$A,row()-2))} | BQ21: {=IF(BB21="","",INDEX(Points!$A:$A,row()-2))} | BR21: {=IF(BC21="","",INDEX(Points!$A:$A,row()-2))} | BS21: {=IF(BD21="","",INDEX(Points!$A:$A,row()-2))} | BT21: {=IF(BE21="","",INDEX(Points!$A:$A,row()-2))} | BU21: {=IF(BF21="","",INDEX(Points!$A:$A,row()-2))} | BV21: {=IF(BG21="","",INDEX(Points!$A:$A,row()-2))} | ... CC21: {=IF(BN21="","",INDEX(Points!$A:$A,row()-2))} | CD21: =index($AZ$3:$BF$100,Mod(row()-3,$CD$1)+1,int((row()-3)/$CD$1)+1) | CE21: =IFERROR(__xludf.DUMMYFUNCTION("""COMPUTED_VALUE"""),"Ragdoll") -> Ragdoll | CF21: =if(CE21="","",sum(CG21:CU21)) -> 297 | CG21: =if($CE21="","",sumif(AZ:AZ,$CE21,BO:BO)) -> 0 | CH21: =if($CE21="","",sumif(BA:BA,$CE21,BP:BP)) -> 0 | CI21: =if($CE21="","",sumif(BB:BB,$CE21,BQ:BQ)) -> 0 | CJ21: =if($CE21="","",sumif(BC:BC,$CE21,BR:BR)) -> 0 | CK21: =if($CE21="","",sumif(BD:BD,$CE21,BS:BS)) -> 0 | CL21: =if($CE21="","",sumif(BE:BE,$CE21,BT:BT)) -> 99 | CM21: =if($CE21="","",sumif(BF:BF,$CE21,BU:BU)) -> 0 | CN21: =if($CE21="","",sumif(BG:BG,$CE21,BV:BV)) -> 0 | CO21: =if($CE21="","",sumif(BH:BH,$CE21,BW:BW)) -> 0 | CP21: =if($CE21="","",sumif(BI:BI,$CE21,BX:BX)) -> 0 | CQ21: =if($CE21="","",sumif(BJ:BJ,$CE21,BY:BY)) -> 0 | CR21: =if($CE21="","",sumif(BK:BK,$CE21,BZ:BZ)) -> 0 | CS21: =if($CE21="","",sumif(BL:BL,$CE21,CA:CA)) -> 0 | CT21: =if($CE21="","",sumif(BM:BM,$CE21,CB:CB)) -> 99 | CU21: =if($CE21="","",sumif(BN:BN,$CE21,CC:CC)) -> 99
R22: =if(T22="","",rank(T22,T:T,false)) -> 20 | S22: Romy | T22: 200 | U22: 0 | V22: 0 | W22: 100 | X22: 0 | Y22: 0 | Z22: 0 | AA22: 0 | AB22: 0 | AC22: 0 | AD22: 0 | AE22: 100 | AF22: 0 | AG22: 0 | AH22: 0 | AI22: 0 | AK22: =iferror(find(" ",B22) ,"") | AL22: =iferror(find(" ",C22) ,"") | AM22: =iferror(find(" ",D22) ,"") | AN22: =iferror(find(" ",E22) ,"") | AO22: =iferror(find(" ",F22) ,"") | AP22: =iferror(find(" ",G22) ,"") | AQ22: =iferror(find(" ",H22) ,"") | AR22: =iferror(find(" ",I22) ,"") | ... AY22: =iferror(find(" ",P22) ,"") | AZ22: =if(and(len(B22)>0,AK22=""),B22,iferror(left(B22, AK22-1),"")) | BA22: =if(and(len(C22)>0,AL22=""),C22,iferror(left(C22, AL22-1),"")) | BB22: =if(and(len(D22)>0,AM22=""),D22,iferror(left(D22, AM22-1),"")) | BC22: =if(and(len(E22)>0,AN22=""),E22,iferror(left(E22, AN22-1),"")) | BD22: =if(and(len(F22)>0,AO22=""),F22,iferror(left(F22, AO22-1),"")) | BE22: =if(and(len(G22)>0,AP22=""),G22,iferror(left(G22, AP22-1),"")) | BF22: =if(and(len(H22)>0,AQ22=""),H22,iferror(left(H22, AQ22-1),"")) | BG22: =if(and(len(I22)>0,AR22=""),I22,iferror(left(I22, AR22-1),"")) | ... BN22: =if(and(len(P22)>0,AY22=""),P22,iferror(left(P22, AY22-1),"")) | BO22: {=IF(AZ22="","",INDEX(Points!$A:$A,row()-2))} | BP22: {=IF(BA22="","",INDEX(Points!$A:$A,row()-2))} | BQ22: {=IF(BB22="","",INDEX(Points!$A:$A,row()-2))} | BR22: {=IF(BC22="","",INDEX(Points!$A:$A,row()-2))} | BS22: {=IF(BD22="","",INDEX(Points!$A:$A,row()-2))} | BT22: {=IF(BE22="","",INDEX(Points!$A:$A,row()-2))} | BU22: {=IF(BF22="","",INDEX(Points!$A:$A,row()-2))} | BV22: {=IF(BG22="","",INDEX(Points!$A:$A,row()-2))} | ... CC22: {=IF(BN22="","",INDEX(Points!$A:$A,row()-2))} | CD22: =index($AZ$3:$BF$100,Mod(row()-3,$CD$1)+1,int((row()-3)/$CD$1)+1) | CE22: =IFERROR(__xludf.DUMMYFUNCTION("""COMPUTED_VALUE"""),"Folo") -> Folo | CF22: =if(CE22="","",sum(CG22:CU22)) -> 294 | CG22: =if($CE22="","",sumif(AZ:AZ,$CE22,BO:BO)) -> 0 | CH22: =if($CE22="","",sumif(BA:BA,$CE22,BP:BP)) -> 0 | CI22: =if($CE22="","",sumif(BB:BB,$CE22,BQ:BQ)) -> 0 | CJ22: =if($CE22="","",sumif(BC:BC,$CE22,BR:BR)) -> 0 | CK22: =if($CE22="","",sumif(BD:BD,$CE22,BS:BS)) -> 0 | CL22: =if($CE22="","",sumif(BE:BE,$CE22,BT:BT)) -> 98 | CM22: =if($CE22="","",sumif(BF:BF,$CE22,BU:BU)) -> 0 | CN22: =if($CE22="","",sumif(BG:BG,$CE22,BV:BV)) -> 0 | CO22: =if($CE22="","",sumif(BH:BH,$CE22,BW:BW)) -> 0 | CP22: =if($CE22="","",sumif(BI:BI,$CE22,BX:BX)) -> 0 | CQ22: =if($CE22="","",sumif(BJ:BJ,$CE22,BY:BY)) -> 0 | CR22: =if($CE22="","",sumif(BK:BK,$CE22,BZ:BZ)) -> 0 | CS22: =if($CE22="","",sumif(BL:BL,$CE22,CA:CA)) -> 0 | CT22: =if($CE22="","",sumif(BM:BM,$CE22,CB:CB)) -> 98 | CU22: =if($CE22="","",sumif(BN:BN,$CE22,CC:CC)) -> 98
