Workbook

Sheet ScoreMatrix
B1: =IFERROR(__xludf.DUMMYFUNCTION("if(Input!B$1="""",,if(len(Input!B$1)<30,offset(Input!$A$1,0,column()-1,51),importrange(Input!B$1,""Sheet1!a1:a51"")))"),"Greddit2") -> Greddit2 | C1: =IFERROR(__xludf.DUMMYFUNCTION("if(Input!C$1="""",,if(len(Input!C$1)<30,offset(Input!$A$1,0,column()-1,51),importrange(Input!C$1,""Sheet1!a1:a51"")))"),"NORTH") -> NORTH | D1: =IFERROR(__xludf.DUMMYFUNCTION("if(Input!D$1="""",,if(len(Input!D$1)<30,offset(Input!$A$1,0,column()-1,51),importrange(Input!D$1,""Sheet1!a1:a51"")))"),"pl") -> pl | E1: =IFERROR(__xludf.DUMMYFUNCTION("if(Input!E$1="""",,if(len(Input!E$1)<30,offset(Input!$A$1,0,column()-1,51),importrange(Input!E$1,""Sheet1!a1:a51"")))"),"sebg") -> sebg | F1: =IFERROR(__xludf.DUMMYFUNCTION("if(Input!F$1="""",,if(len(Input!F$1)<30,offset(Input!$A$1,0,column()-1,51),importrange(Input!F$1,""Sheet1!a1:a51"")))"),"") | G1: =IFERROR(__xludf.DUMMYFUNCTION("if(Input!G$1="""",,if(len(Input!G$1)<30,offset(Input!$A$1,0,column()-1,51),importrange(Input!G$1,""Sheet1!a1:a51"")))"),"") | H1: =IFERROR(__xludf.DUMMYFUNCTION("if(Input!H$1="""",,if(len(Input!H$1)<30,offset(Input!$A$1,0,column()-1,51),importrange(Input!H$1,""Sheet1!a1:a51"")))"),"") | I1: =IFERROR(__xludf.DUMMYFUNCTION("if(Input!I$1="""",,if(len(Input!I$1)<30,offset(Input!$A$1,0,column()-1,51),importrange(Input!I$1,""Sheet1!a1:a51"")))"),"") | J1: =IFERROR(__xludf.DUMMYFUNCTION("if(Input!J$1="""",,if(len(Input!J$1)<30,offset(Input!$A$1,0,column()-1,51),importrange(Input!J$1,""Sheet1!a1:a51"")))"),"") | K1: =IFERROR(__xludf.DUMMYFUNCTION("if(Input!K$1="""",,if(len(Input!K$1)<30,offset(Input!$A$1,0,column()-1,51),importrange(Input!K$1,""Sheet1!a1:a51"")))"),"") | L1: =IFERROR(__xludf.DUMMYFUNCTION("if(Input!L$1="""",,if(len(Input!L$1)<30,offset(Input!$A$1,0,column()-1,51),importrange(Input!L$1,""Sheet1!a1:a51"")))"),"") | M1: =IFERROR(__xludf.DUMMYFUNCTION("if(Input!M$1="""",,if(len(Input!M$1)<30,offset(Input!$A$1,0,column()-1,51),importrange(Input!M$1,""Sheet1!a1:a51"")))"),"") | N1: =IFERROR(__xludf.DUMMYFUNCTION("if(Input!N$1="""",,if(len(Input!N$1)<30,offset(Input!$A$1,0,column()-1,51),importrange(Input!N$1,""Sheet1!a1:a51"")))"),"") | O1: =IFERROR(__xludf.DUMMYFUNCTION("if(Input!O$1="""",,if(len(Input!O$1)<30,offset(Input!$A$1,0,column()-1,51),importrange(Input!O$1,""Sheet1!a1:a51"")))"),"") | P1: =IFERROR(__xludf.DUMMYFUNCTION("if(Input!P$1="""",,if(len(Input!P$1)<30,offset(Input!$A$1,0,column()-1,51),importrange(Input!P$1,""Sheet1!a1:a51"")))"),"") | Q1: =IFERROR(__xludf.DUMMYFUNCTION("if(Input!Q$1="""",,if(len(Input!Q$1)<30,offset(Input!$A$1,0,column()-1,51),importrange(Input!Q$1,""Sheet1!a1:a51"")))"),"") | R1: =IFERROR(__xludf.DUMMYFUNCTION("if(Input!R$1="""",,if(len(Input!R$1)<30,offset(Input!$A$1,0,column()-1,51),importrange(Input!R$1,""Sheet1!a1:a51"")))"),"") | S1: =IFERROR(__xludf.DUMMYFUNCTION("if(Input!S$1="""",,if(len(Input!S$1)<30,offset(Input!$A$1,0,column()-1,51),importrange(Input!S$1,""Sheet1!a1:a51"")))"),"") | T1: =IFERROR(__xludf.DUMMYFUNCTION("if(Input!T$1="""",,if(len(Input!T$1)<30,offset(Input!$A$1,0,column()-1,51),importrange(Input!T$1,""Sheet1!a1:a51"")))"),"") | U1: =IFERROR(__xludf.DUMMYFUNCTION("if(Input!U$1="""",,if(len(Input!U$1)<30,offset(Input!$A$1,0,column()-1,51),importrange(Input!U$1,""Sheet1!a1:a51"")))"),"") | V1: =IFERROR(__xludf.DUMMYFUNCTION("if(Input!V$1="""",,if(len(Input!V$1)<30,offset(Input!$A$1,0,column()-1,51),importrange(Input!V$1,""Sheet1!a1:a51"")))"),"") | W1: =IFERROR(__xludf.DUMMYFUNCTION("if(Input!W$1="""",,if(len(Input!W$1)<30,offset(Input!$A$1,0,column()-1,51),importrange(Input!W$1,""Sheet1!a1:a51"")))"),"") | X1: =IFERROR(__xludf.DUMMYFUNCTION("if(Input!X$1="""",,if(len(Input!X$1)<30,offset(Input!$A$1,0,column()-1,51),importrange(Input!X$1,""Sheet1!a1:a51"")))"),"") | Y1: =IFERROR(__xludf.DUMMYFUNCTION("if(Input!Y$1="""",,if(len(Input!Y$1)<30,offset(Input!$A$1,0,column()-1,51),importrange(Input!Y$1,""Sheet1!a1:a51"")))"),"") | Z1: =IFERROR(__xludf.DUMMYFUNCTION("if(Input!Z$1="""",,if(len(Input!Z$1)<30,offset(Input!$A$1,0,column()-1,51),importrange(Input!Z$1,""Sheet1!a1:a51"")))"),"") | AA1: =IFERROR(__xludf.DUMMYFUNCTION("if(Input!AA$1="""",,if(len(Input!AA$1)<30,offset(Input!$A$1,0,column()-1,51),importrange(Input!AA$1,""Sheet1!a1:a51"")))"),"")
B2: =IFERROR(__xludf.DUMMYFUNCTION("""COMPUTED_VALUE"""),37750.0) -> 37750 | C2: =IFERROR(__xludf.DUMMYFUNCTION("""COMPUTED_VALUE"""),38399.0) -> 38399 | D2: =IFERROR(__xludf.DUMMYFUNCTION("""COMPUTED_VALUE"""),42626.0) -> 42626 | E2: =IFERROR(__xludf.DUMMYFUNCTION("""COMPUTED_VALUE"""),41338.0) -> 41338
B3: =IFERROR(__xludf.DUMMYFUNCTION("""COMPUTED_VALUE"""),36340.0) -> 36340 | C3: =IFERROR(__xludf.DUMMYFUNCTION("""COMPUTED_VALUE"""),38021.0) -> 38021 | D3: =IFERROR(__xludf.DUMMYFUNCTION("""COMPUTED_VALUE"""),41118.0) -> 41118 | E3: =IFERROR(__xludf.DUMMYFUNCTION("""COMPUTED_VALUE"""),41153.0) -> 41153
B4: =IFERROR(__xludf.DUMMYFUNCTION("""COMPUTED_VALUE"""),36148.0) -> 36148 | C4: =IFERROR(__xludf.DUMMYFUNCTION("""COMPUTED_VALUE"""),37631.0) -> 37631 | D4: =IFERROR(__xludf.DUMMYFUNCTION("""COMPUTED_VALUE"""),41042.0) -> 41042 | E4: =IFERROR(__xludf.DUMMYFUNCTION("""COMPUTED_VALUE"""),40912.0) -> 40912
B5: =IFERROR(__xludf.DUMMYFUNCTION("""COMPUTED_VALUE"""),35606.0) -> 35606 | C5: =IFERROR(__xludf.DUMMYFUNCTION("""COMPUTED_VALUE"""),36965.0) -> 36965 | D5: =IFERROR(__xludf.DUMMYFUNCTION("""COMPUTED_VALUE"""),40807.0) -> 40807 | E5: =IFERROR(__xludf.DUMMYFUNCTION("""COMPUTED_VALUE"""),40742.0) -> 40742
B6: =IFERROR(__xludf.DUMMYFUNCTION("""COMPUTED_VALUE"""),34977.0) -> 34977 | C6: =IFERROR(__xludf.DUMMYFUNCTION("""COMPUTED_VALUE"""),36944.0) -> 36944 | D6: =IFERROR(__xludf.DUMMYFUNCTION("""COMPUTED_VALUE"""),40750.0) -> 40750 | E6: =IFERROR(__xludf.DUMMYFUNCTION("""COMPUTED_VALUE"""),40581.0) -> 40581
B7: =IFERROR(__xludf.DUMMYFUNCTION("""COMPUTED_VALUE"""),34868.0) -> 34868 | C7: =IFERROR(__xludf.DUMMYFUNCTION("""COMPUTED_VALUE"""),36620.0) -> 36620 | D7: =IFERROR(__xludf.DUMMYFUNCTION("""COMPUTED_VALUE"""),40655.0) -> 40655 | E7: =IFERROR(__xludf.DUMMYFUNCTION("""COMPUTED_VALUE"""),40522.0) -> 40522
B8: =IFERROR(__xludf.DUMMYFUNCTION("""COMPUTED_VALUE"""),34771.0) -> 34771 | C8: =IFERROR(__xludf.DUMMYFUNCTION("""COMPUTED_VALUE"""),36554.0) -> 36554 | D8: =IFERROR(__xludf.DUMMYFUNCTION("""COMPUTED_VALUE"""),40576.0) -> 40576 | E8: =IFERROR(__xludf.DUMMYFUNCTION("""COMPUTED_VALUE"""),40504.0) -> 40504
B9: =IFERROR(__xludf.DUMMYFUNCTION("""COMPUTED_VALUE"""),34706.0) -> 34706 | C9: =IFERROR(__xludf.DUMMYFUNCTION("""COMPUTED_VALUE"""),36175.0) -> 36175 | D9: =IFERROR(__xludf.DUMMYFUNCTION("""COMPUTED_VALUE"""),40392.0) -> 40392 | E9: =IFERROR(__xludf.DUMMYFUNCTION("""COMPUTED_VALUE"""),40489.0) -> 40489
B10: =IFERROR(__xludf.DUMMYFUNCTION("""COMPUTED_VALUE"""),34326.0) -> 34326 | C10: =IFERROR(__xludf.DUMMYFUNCTION("""COMPUTED_VALUE"""),35857.0) -> 35857 | D10: =IFERROR(__xludf.DUMMYFUNCTION("""COMPUTED_VALUE"""),40209.0) -> 40209 | E10: =IFERROR(__xludf.DUMMYFUNCTION("""COMPUTED_VALUE"""),40405.0) -> 40405
B11: =IFERROR(__xludf.DUMMYFUNCTION("""COMPUTED_VALUE"""),33276.0) -> 33276 | C11: =IFERROR(__xludf.DUMMYFUNCTION("""COMPUTED_VALUE"""),35783.0) -> 35783 | D11: =IFERROR(__xludf.DUMMYFUNCTION("""COMPUTED_VALUE"""),40078.0) -> 40078 | E11: =IFERROR(__xludf.DUMMYFUNCTION("""COMPUTED_VALUE"""),39935.0) -> 39935
B12: =IFERROR(__xludf.DUMMYFUNCTION("""COMPUTED_VALUE"""),33091.0) -> 33091 | C12: =IFERROR(__xludf.DUMMYFUNCTION("""COMPUTED_VALUE"""),35463.0) -> 35463 | D12: =IFERROR(__xludf.DUMMYFUNCTION("""COMPUTED_VALUE"""),40059.0) -> 40059 | E12: =IFERROR(__xludf.DUMMYFUNCTION("""COMPUTED_VALUE"""),39896.0) -> 39896
B13: =IFERROR(__xludf.DUMMYFUNCTION("""COMPUTED_VALUE"""),32689.0) -> 32689 | C13: =IFERROR(__xludf.DUMMYFUNCTION("""COMPUTED_VALUE"""),35391.0) -> 35391 | D13: =IFERROR(__xludf.DUMMYFUNCTION("""COMPUTED_VALUE"""),40038.0) -> 40038 | E13: =IFERROR(__xludf.DUMMYFUNCTION("""COMPUTED_VALUE"""),39882.0) -> 39882
B14: =IFERROR(__xludf.DUMMYFUNCTION("""COMPUTED_VALUE"""),32649.0) -> 32649 | C14: =IFERROR(__xludf.DUMMYFUNCTION("""COMPUTED_VALUE"""),35365.0) -> 35365 | D14: =IFERROR(__xludf.DUMMYFUNCTION("""COMPUTED_VALUE"""),39942.0) -> 39942 | E14: =IFERROR(__xludf.DUMMYFUNCTION("""COMPUTED_VALUE"""),39845.0) -> 39845
B15: =IFERROR(__xludf.DUMMYFUNCTION("""COMPUTED_VALUE"""),32339.0) -> 32339 | C15: =IFERROR(__xludf.DUMMYFUNCTION("""COMPUTED_VALUE"""),35287.0) -> 35287 | D15: =IFERROR(__xludf.DUMMYFUNCTION("""COMPUTED_VALUE"""),39931.0) -> 39931 | E15: =IFERROR(__xludf.DUMMYFUNCTION("""COMPUTED_VALUE"""),39809.0) -> 39809
B16: =IFERROR(__xludf.DUMMYFUNCTION("""COMPUTED_VALUE"""),32251.0) -> 32251 | C16: =IFERROR(__xludf.DUMMYFUNCTION("""COMPUTED_VALUE"""),35245.0) -> 35245 | D16: =IFERROR(__xludf.DUMMYFUNCTION("""COMPUTED_VALUE"""),39843.0) -> 39843 | E16: =IFERROR(__xludf.DUMMYFUNCTION("""COMPUTED_VALUE"""),39611.0) -> 39611
B17: =IFERROR(__xludf.DUMMYFUNCTION("""COMPUTED_VALUE"""),32135.0) -> 32135 | C17: =IFERROR(__xludf.DUMMYFUNCTION("""COMPUTED_VALUE"""),35061.0) -> 35061 | D17: =IFERROR(__xludf.DUMMYFUNCTION("""COMPUTED_VALUE"""),39705.0) -> 39705 | E17: =IFERROR(__xludf.DUMMYFUNCTION("""COMPUTED_VALUE"""),39589.0) -> 39589
B18: =IFERROR(__xludf.DUMMYFUNCTION("""COMPUTED_VALUE"""),31931.0) -> 31931 | C18: =IFERROR(__xludf.DUMMYFUNCTION("""COMPUTED_VALUE"""),34992.0) -> 34992 | D18: =IFERROR(__xludf.DUMMYFUNCTION("""COMPUTED_VALUE"""),39669.0) -> 39669 | E18: =IFERROR(__xludf.DUMMYFUNCTION("""COMPUTED_VALUE"""),39588.0) -> 39588
B19: =IFERROR(__xludf.DUMMYFUNCTION("""COMPUTED_VALUE"""),31865.0) -> 31865 | C19: =IFERROR(__xludf.DUMMYFUNCTION("""COMPUTED_VALUE"""),34978.0) -> 34978 | D19: =IFERROR(__xludf.DUMMYFUNCTION("""COMPUTED_VALUE"""),39563.0) -> 39563 | E19: =IFERROR(__xludf.DUMMYFUNCTION("""COMPUTED_VALUE"""),39502.0) -> 39502
B20: =IFERROR(__xludf.DUMMYFUNCTION("""COMPUTED_VALUE"""),31836.0) -> 31836 | C20: =IFERROR(__xludf.DUMMYFUNCTION("""COMPUTED_VALUE"""),34802.0) -> 34802 | D20: =IFERROR(__xludf.DUMMYFUNCTION("""COMPUTED_VALUE"""),39277.0) -> 39277 | E20: =IFERROR(__xludf.DUMMYFUNCTION("""COMPUTED_VALUE"""),39387.0) -> 39387
B21: =IFERROR(__xludf.DUMMYFUNCTION("""COMPUTED_VALUE"""),31777.0) -> 31777 | C21: =IFERROR(__xludf.DUMMYFUNCTION("""COMPUTED_VALUE"""),34578.0) -> 34578 | D21: =IFERROR(__xludf.DUMMYFUNCTION("""COMPUTED_VALUE"""),39220.0) -> 39220 | E21: =IFERROR(__xludf.DUMMYFUNCTION("""COMPUTED_VALUE"""),39068.0) -> 39068
B22: =IFERROR(__xludf.DUMMYFUNCTION("""COMPUTED_VALUE"""),31572.0) -> 31572 | C22: =IFERROR(__xludf.DUMMYFUNCTION("""COMPUTED_VALUE"""),34575.0) -> 34575 | D22: =IFERROR(__xludf.DUMMYFUNCTION("""COMPUTED_VALUE"""),39203.0) -> 39203 | E22: =IFERROR(__xludf.DUMMYFUNCTION("""COMPUTED_VALUE"""),39040.0) -> 39040
B23: =IFERROR(__xludf.DUMMYFUNCTION("""COMPUTED_VALUE"""),31508.0) -> 31508 | C23: =IFERROR(__xludf.DUMMYFUNCTION("""COMPUTED_VALUE"""),34453.0) -> 34453 | D23: =IFERROR(__xludf.DUMMYFUNCTION("""COMPUTED_VALUE"""),39099.0) -> 39099 | E23: =IFERROR(__xludf.DUMMYFUNCTION("""COMPUTED_VALUE"""),38888.0) -> 38888
B24: =IFERROR(__xludf.DUMMYFUNCTION("""COMPUTED_VALUE"""),31410.0) -> 31410 | C24: =IFERROR(__xludf.DUMMYFUNCTION("""COMPUTED_VALUE"""),34312.0) -> 34312 | D24: =IFERROR(__xludf.DUMMYFUNCTION("""COMPUTED_VALUE"""),39000.0) -> 39000 | E24: =IFERROR(__xludf.DUMMYFUNCTION("""COMPUTED_VALUE"""),38696.0) -> 38696
B25: =IFERROR(__xludf.DUMMYFUNCTION("""COMPUTED_VALUE"""),31190.0) -> 31190 | C25: =IFERROR(__xludf.DUMMYFUNCTION("""COMPUTED_VALUE"""),34154.0) -> 34154 | D25: =IFERROR(__xludf.DUMMYFUNCTION("""COMPUTED_VALUE"""),38991.0) -> 38991 | E25: =IFERROR(__xludf.DUMMYFUNCTION("""COMPUTED_VALUE"""),38660.0) -> 38660
B26: =IFERROR(__xludf.DUMMYFUNCTION("""COMPUTED_VALUE"""),31107.0) -> 31107 | C26: =IFERROR(__xludf.DUMMYFUNCTION("""COMPUTED_VALUE"""),34050.0) -> 34050 | D26: =IFERROR(__xludf.DUMMYFUNCTION("""COMPUTED_VALUE"""),38925.0) -> 38925 | E26: =IFERROR(__xludf.DUMMYFUNCTION("""COMPUTED_VALUE"""),38615.0) -> 38615
B27: =IFERROR(__xludf.DUMMYFUNCTION("""COMPUTED_VALUE"""),30982.0) -> 30982 | C27: =IFERROR(__xludf.DUMMYFUNCTION("""COMPUTED_VALUE"""),33741.0) -> 33741 | D27: =IFERROR(__xludf.DUMMYFUNCTION("""COMPUTED_VALUE"""),38685.0) -> 38685 | E27: =IFERROR(__xludf.DUMMYFUNCTION("""COMPUTED_VALUE"""),38568.0) -> 38568
B28: =IFERROR(__xludf.DUMMYFUNCTION("""COMPUTED_VALUE"""),30980.0) -> 30980 | C28: =IFERROR(__xludf.DUMMYFUNCTION("""COMPUTED_VALUE"""),33568.0) -> 33568 | D28: =IFERROR(__xludf.DUMMYFUNCTION("""COMPUTED_VALUE"""),38653.0) -> 38653 | E28: =IFERROR(__xludf.DUMMYFUNCTION("""COMPUTED_VALUE"""),38567.0) -> 38567
B29: =IFERROR(__xludf.DUMMYFUNCTION("""COMPUTED_VALUE"""),30663.0) -> 30663 | C29: =IFERROR(__xludf.DUMMYFUNCTION("""COMPUTED_VALUE"""),33353.0) -> 33353 | D29: =IFERROR(__xludf.DUMMYFUNCTION("""COMPUTED_VALUE"""),38647.0) -> 38647 | E29: =IFERROR(__xludf.DUMMYFUNCTION("""COMPUTED_VALUE"""),38553.0) -> 38553
B30: =IFERROR(__xludf.DUMMYFUNCTION("""COMPUTED_VALUE"""),30571.0) -> 30571 | C30: =IFERROR(__xludf.DUMMYFUNCTION("""COMPUTED_VALUE"""),33174.0) -> 33174 | D30: =IFERROR(__xludf.DUMMYFUNCTION("""COMPUTED_VALUE"""),38474.0) -> 38474 | E30: =IFERROR(__xludf.DUMMYFUNCTION("""COMPUTED_VALUE"""),38549.0) -> 38549
B31: =IFERROR(__xludf.DUMMYFUNCTION("""COMPUTED_VALUE"""),30569.0) -> 30569 | C31: =IFERROR(__xludf.DUMMYFUNCTION("""COMPUTED_VALUE"""),33111.0) -> 33111 | D31: =IFERROR(__xludf.DUMMYFUNCTION("""COMPUTED_VALUE"""),38344.0) -> 38344 | E31: =IFERROR(__xludf.DUMMYFUNCTION("""COMPUTED_VALUE"""),38501.0) -> 38501
B32: =IFERROR(__xludf.DUMMYFUNCTION("""COMPUTED_VALUE"""),30495.0) -> 30495 | C32: =IFERROR(__xludf.DUMMYFUNCTION("""COMPUTED_VALUE"""),33104.0) -> 33104 | D32: =IFERROR(__xludf.DUMMYFUNCTION("""COMPUTED_VALUE"""),38321.0) -> 38321 | E32: =IFERROR(__xludf.DUMMYFUNCTION("""COMPUTED_VALUE"""),38493.0) -> 38493
B33: =IFERROR(__xludf.DUMMYFUNCTION("""COMPUTED_VALUE"""),30043.0) -> 30043 | C33: =IFERROR(__xludf.DUMMYFUNCTION("""COMPUTED_VALUE"""),33032.0) -> 33032 | D33: =IFERROR(__xludf.DUMMYFUNCTION("""COMPUTED_VALUE"""),38310.0) -> 38310 | E33: =IFERROR(__xludf.DUMMYFUNCTION("""COMPUTED_VALUE"""),38447.0) -> 38447
B34: =IFERROR(__xludf.DUMMYFUNCTION("""COMPUTED_VALUE"""),29764.0) -> 29764 | C34: =IFERROR(__xludf.DUMMYFUNCTION("""COMPUTED_VALUE"""),32816.0) -> 32816 | D34: =IFERROR(__xludf.DUMMYFUNCTION("""COMPUTED_VALUE"""),37896.0) -> 37896 | E34: =IFERROR(__xludf.DUMMYFUNCTION("""COMPUTED_VALUE"""),38394.0) -> 38394
B35: =IFERROR(__xludf.DUMMYFUNCTION("""COMPUTED_VALUE"""),29227.0) -> 29227 | C35: =IFERROR(__xludf.DUMMYFUNCTION("""COMPUTED_VALUE"""),32649.0) -> 32649 | D35: =IFERROR(__xludf.DUMMYFUNCTION("""COMPUTED_VALUE"""),37634.0) -> 37634 | E35: =IFERROR(__xludf.DUMMYFUNCTION("""COMPUTED_VALUE"""),38376.0) -> 38376
B36: =IFERROR(__xludf.DUMMYFUNCTION("""COMPUTED_VALUE"""),29157.0) -> 29157 | C36: =IFERROR(__xludf.DUMMYFUNCTION("""COMPUTED_VALUE"""),32595.0) -> 32595 | D36: =IFERROR(__xludf.DUMMYFUNCTION("""COMPUTED_VALUE"""),37584.0) -> 37584 | E36: =IFERROR(__xludf.DUMMYFUNCTION("""COMPUTED_VALUE"""),38363.0) -> 38363
B37: =IFERROR(__xludf.DUMMYFUNCTION("""COMPUTED_VALUE"""),28798.0) -> 28798 | C37: =IFERROR(__xludf.DUMMYFUNCTION("""COMPUTED_VALUE"""),32292.0) -> 32292 | D37: =IFERROR(__xludf.DUMMYFUNCTION("""COMPUTED_VALUE"""),37135.0) -> 37135 | E37: =IFERROR(__xludf.DUMMYFUNCTION("""COMPUTED_VALUE"""),38115.0) -> 38115
B38: =IFERROR(__xludf.DUMMYFUNCTION("""COMPUTED_VALUE"""),28796.0) -> 28796 | C38: =IFERROR(__xludf.DUMMYFUNCTION("""COMPUTED_VALUE"""),32216.0) -> 32216 | D38: =IFERROR(__xludf.DUMMYFUNCTION("""COMPUTED_VALUE"""),37060.0) -> 37060 | E38: =IFERROR(__xludf.DUMMYFUNCTION("""COMPUTED_VALUE"""),38076.0) -> 38076
B39: =IFERROR(__xludf.DUMMYFUNCTION("""COMPUTED_VALUE"""),28733.0) -> 28733 | C39: =IFERROR(__xludf.DUMMYFUNCTION("""COMPUTED_VALUE"""),32041.0) -> 32041 | D39: =IFERROR(__xludf.DUMMYFUNCTION("""COMPUTED_VALUE"""),37053.0) -> 37053 | E39: =IFERROR(__xludf.DUMMYFUNCTION("""COMPUTED_VALUE"""),38013.0) -> 38013
B40: =IFERROR(__xludf.DUMMYFUNCTION("""COMPUTED_VALUE"""),28663.0) -> 28663 | C40: =IFERROR(__xludf.DUMMYFUNCTION("""COMPUTED_VALUE"""),31701.0) -> 31701 | D40: =IFERROR(__xludf.DUMMYFUNCTION("""COMPUTED_VALUE"""),36989.0) -> 36989 | E40: =IFERROR(__xludf.DUMMYFUNCTION("""COMPUTED_VALUE"""),37944.0) -> 37944
...

Sheet VirtualLeague
B1: Formatted for Discord | C1: Virtual League
A2: # | B2: __**Team Leaderboard**__ | C2: Team | D2: Score | E2: # | F2: Average | G2: Team | H2: Total | I2: =IFERROR(__xludf.DUMMYFUNCTION("Iferror(if(Input!B1="""",,if(len(Input!B1)<30,{Input!B1},importrange(Input!B1,""Sheet1!a1:a1""))),)"),"Greddit2") -> Greddit2 | J2: =IFERROR(__xludf.DUMMYFUNCTION("Iferror(if(Input!C1="""",,if(len(Input!C1)<30,{Input!C1},importrange(Input!C1,""Sheet1!a1:a1""))),)"),"NORTH") -> NORTH | K2: =IFERROR(__xludf.DUMMYFUNCTION("Iferror(if(Input!D1="""",,if(len(Input!D1)<30,{Input!D1},importrange(Input!D1,""Sheet1!a1:a1""))),)"),"pl") -> pl | L2: =IFERROR(__xludf.DUMMYFUNCTION("Iferror(if(Input!E1="""",,if(len(Input!E1)<30,{Input!E1},importrange(Input!E1,""Sheet1!a1:a1""))),)"),"sebg") -> sebg | M2: =IFERROR(__xludf.DUMMYFUNCTION("Iferror(if(Input!F1="""",,if(len(Input!F1)<30,{Input!F1},importrange(Input!F1,""Sheet1!a1:a1""))),)"),"") | N2: =IFERROR(__xludf.DUMMYFUNCTION("Iferror(if(Input!G1="""",,if(len(Input!G1)<30,{Input!G1},importrange(Input!G1,""Sheet1!a1:a1""))),)"),"") | O2: =IFERROR(__xludf.DUMMYFUNCTION("Iferror(if(Input!H1="""",,if(len(Input!H1)<30,{Input!H1},importrange(Input!H1,""Sheet1!a1:a1""))),)"),"") | P2: =IFERROR(__xludf.DUMMYFUNCTION("Iferror(if(Input!I1="""",,if(len(Input!I1)<30,{Input!I1},importrange(Input!I1,""Sheet1!a1:a1""))),)"),"") | Q2: =IFERROR(__xludf.DUMMYFUNCTION("Iferror(if(Input!J1="""",,if(len(Input!J1)<30,{Input!J1},importrange(Input!J1,""Sheet1!a1:a1""))),)"),"") | R2: =IFERROR(__xludf.DUMMYFUNCTION("Iferror(if(Input!K1="""",,if(len(Input!K1)<30,{Input!K1},importrange(Input!K1,""Sheet1!a1:a1""))),)"),"") | S2: =IFERROR(__xludf.DUMMYFUNCTION("Iferror(if(Input!L1="""",,if(len(Input!L1)<30,{Input!L1},importrange(Input!L1,""Sheet1!a1:a1""))),)"),"") | T2: =IFERROR(__xludf.DUMMYFUNCTION("Iferror(if(Input!M1="""",,if(len(Input!M1)<30,{Input!M1},importrange(Input!M1,""Sheet1!a1:a1""))),)"),"") | U2: =IFERROR(__xludf.DUMMYFUNCTION("Iferror(if(Input!N1="""",,if(len(Input!N1)<30,{Input!N1},importrange(Input!N1,""Sheet1!a1:a1""))),)"),"") | V2: =IFERROR(__xludf.DUMMYFUNCTION("Iferror(if(Input!O1="""",,if(len(Input!O1)<30,{Input!O1},importrange(Input!O1,""Sheet1!a1:a1""))),)"),"") | W2: =IFERROR(__xludf.DUMMYFUNCTION("Iferror(if(Input!P1="""",,if(len(Input!P1)<30,{Input!P1},importrange(Input!P1,""Sheet1!a1:a1""))),)"),"") | X2: =IFERROR(__xludf.DUMMYFUNCTION("Iferror(if(Input!Q1="""",,if(len(Input!Q1)<30,{Input!Q1},importrange(Input!Q1,""Sheet1!a1:a1""))),)"),"") | Y2: =IFERROR(__xludf.DUMMYFUNCTION("Iferror(if(Input!R1="""",,if(len(Input!R1)<30,{Input!R1},importrange(Input!R1,""Sheet1!a1:a1""))),)"),"") | Z2: =IFERROR(__xludf.DUMMYFUNCTION("Iferror(if(Input!S1="""",,if(len(Input!S1)<30,{Input!S1},importrange(Input!S1,""Sheet1!a1:a1""))),)"),"") | AA2: =IFERROR(__xludf.DUMMYFUNCTION("Iferror(if(Input!T1="""",,if(len(Input!T1)<30,{Input!T1},importrange(Input!T1,""Sheet1!a1:a1""))),)"),"") | AB2: =IFERROR(__xludf.DUMMYFUNCTION("Iferror(if(Input!U1="""",,if(len(Input!U1)<30,{Input!U1},importrange(Input!U1,""Sheet1!a1:a1""))),)"),"") | AC2: =IFERROR(__xludf.DUMMYFUNCTION("Iferror(if(Input!V1="""",,if(len(Input!V1)<30,{Input!V1},importrange(Input!V1,""Sheet1!a1:a1""))),)"),"") | AD2: =IFERROR(__xludf.DUMMYFUNCTION("Iferror(if(Input!W1="""",,if(len(Input!W1)<30,{Input!W1},importrange(Input!W1,""Sheet1!a1:a1""))),)"),"") | AE2: =IFERROR(__xludf.DUMMYFUNCTION("Iferror(if(Input!X1="""",,if(len(Input!X1)<30,{Input!X1},importrange(Input!X1,""Sheet1!a1:a1""))),)"),"") | AF2: =IFERROR(__xludf.DUMMYFUNCTION("Iferror(if(Input!Y1="""",,if(len(Input!Y1)<30,{Input!Y1},importrange(Input!Y1,""Sheet1!a1:a1""))),)"),"")
A3: 1 | B3: =if(isblank(VirtualLeague!D3),,"`"&VirtualLeague!C3&rept(" ",20-len(VirtualLeague!C3))& rept(" ",6-len(VirtualLeague!D3))&VirtualLeague!D3&"`" ) -> `pl 10947` | C3: {=sort(VirtualLeague!$G$3:$H$26, VirtualLeague!$H$3:$H$26,false)} -> pl | D3: 10947 | E3: {=if(G3="",,count(index(ScoreMatrix!$B$2:$AA$51,,$A3)))} -> 46 | F3: {=if(G3="",,average(index(ScoreMatrix!$B$2:$AA$51,,$A3)))} -> 31390.957 | G3: =index($I$2:$AF$2,A3) -> Greddit2 | H3: =if(G3="",,sum(I3:AF3)) -> 1582 | I3: {=if(and($G3<>I$2,$G3<>"",I$2<>""),sum(iferror(vlookup(rank(index(ScoreMatrix!$B$2:$AA$51,,$A3),{index(ScoreMatrix!$B$2:$AA$51,,$A3);ScoreMatrix!B$2:B$51},false),RankScores!$A$1:$C$100,3,false)),),)} | J3: {=if(and($G3<>J$2,$G3<>"",J$2<>""),sum(iferror(vlookup(rank(index(ScoreMatrix!$B$2:$AA$51,,$A3),{index(ScoreMatrix!$B$2:$AA$51,,$A3);ScoreMatrix!C$2:C$51},false),RankScores!$A$1:$C$100,3,false)),),)} -> 1158 | K3: {=if(and($G3<>K$2,$G3<>"",K$2<>""),sum(iferror(vlookup(rank(index(ScoreMatrix!$B$2:$AA$51,,$A3),{index(ScoreMatrix!$B$2:$AA$51,,$A3);ScoreMatrix!D$2:D$51},false),RankScores!$A$1:$C$100,3,false)),),)} -> 207 | L3: {=if(and($G3<>L$2,$G3<>"",L$2<>""),sum(iferror(vlookup(rank(index(ScoreMatrix!$B$2:$AA$51,,$A3),{index(ScoreMatrix!$B$2:$AA$51,,$A3);ScoreMatrix!E$2:E$51},false),RankScores!$A$1:$C$100,3,false)),),)} -> 217 | M3: {=if(and($G3<>M$2,$G3<>"",M$2<>""),sum(iferror(vlookup(rank(index(ScoreMatrix!$B$2:$AA$51,,$A3),{index(ScoreMatrix!$B$2:$AA$51,,$A3);ScoreMatrix!F$2:F$51},false),RankScores!$A$1:$C$100,3,false)),),)} | N3: {=if(and($G3<>N$2,$G3<>"",N$2<>""),sum(iferror(vlookup(rank(index(ScoreMatrix!$B$2:$AA$51,,$A3),{index(ScoreMatrix!$B$2:$AA$51,,$A3);ScoreMatrix!G$2:G$51},false),RankScores!$A$1:$C$100,3,false)),),)} | O3: {=if(and($G3<>O$2,$G3<>"",O$2<>""),sum(iferror(vlookup(rank(index(ScoreMatrix!$B$2:$AA$51,,$A3),{index(ScoreMatrix!$B$2:$AA$51,,$A3);ScoreMatrix!H$2:H$51},false),RankScores!$A$1:$C$100,3,false)),),)} | P3: {=if(and($G3<>P$2,$G3<>"",P$2<>""),sum(iferror(vlookup(rank(index(ScoreMatrix!$B$2:$AA$51,,$A3),{index(ScoreMatrix!$B$2:$AA$51,,$A3);ScoreMatrix!I$2:I$51},false),RankScores!$A$1:$C$100,3,false)),),)} | ... AF3: {=if(and($G3<>AF$2,$G3<>"",AF$2<>""),sum(iferror(vlookup(rank(index(ScoreMatrix!$B$2:$AA$51,,$A3),{index(ScoreMatrix!$B$2:$AA$51,,$A3);ScoreMatrix!Y$2:Y$51},false),RankScores!$A$1:$C$100,3,false)),),)}
A4: 2 | B4: =if(isblank(VirtualLeague!D4),,"`"&VirtualLeague!C4&rept(" ",20-len(VirtualLeague!C4))& rept(" ",6-len(VirtualLeague!D4))&VirtualLeague!D4&"`" ) -> `sebg 10713` | C4: sebg | D4: 10713 | E4: {=if(G4="",,count(index(ScoreMatrix!$B$2:$AA$51,,$A4)))} -> 49 | F4: {=if(G4="",,average(index(ScoreMatrix!$B$2:$AA$51,,$A4)))} -> 33887.816 | G4: =index($I$2:$AF$2,A4) -> NORTH | H4: =if(G4="",,sum(I4:AF4)) -> 3903 | I4: {=if(and($G4<>I$2,$G4<>"",I$2<>""),sum(iferror(vlookup(rank(index(ScoreMatrix!$B$2:$AA$51,,$A4),{index(ScoreMatrix!$B$2:$AA$51,,$A4);ScoreMatrix!B$2:B$51},false),RankScores!$A$1:$C$100,3,false)),),)} -> 3364 | J4: {=if(and($G4<>J$2,$G4<>"",J$2<>""),sum(iferror(vlookup(rank(index(ScoreMatrix!$B$2:$AA$51,,$A4),{index(ScoreMatrix!$B$2:$AA$51,,$A4);ScoreMatrix!C$2:C$51},false),RankScores!$A$1:$C$100,3,false)),),)} | K4: {=if(and($G4<>K$2,$G4<>"",K$2<>""),sum(iferror(vlookup(rank(index(ScoreMatrix!$B$2:$AA$51,,$A4),{index(ScoreMatrix!$B$2:$AA$51,,$A4);ScoreMatrix!D$2:D$51},false),RankScores!$A$1:$C$100,3,false)),),)} -> 275 | L4: {=if(and($G4<>L$2,$G4<>"",L$2<>""),sum(iferror(vlookup(rank(index(ScoreMatrix!$B$2:$AA$51,,$A4),{index(ScoreMatrix!$B$2:$AA$51,,$A4);ScoreMatrix!E$2:E$51},false),RankScores!$A$1:$C$100,3,false)),),)} -> 264 | M4: {=if(and($G4<>M$2,$G4<>"",M$2<>""),sum(iferror(vlookup(rank(index(ScoreMatrix!$B$2:$AA$51,,$A4),{index(ScoreMatrix!$B$2:$AA$51,,$A4);ScoreMatrix!F$2:F$51},false),RankScores!$A$1:$C$100,3,false)),),)} | N4: {=if(and($G4<>N$2,$G4<>"",N$2<>""),sum(iferror(vlookup(rank(index(ScoreMatrix!$B$2:$AA$51,,$A4),{index(ScoreMatrix!$B$2:$AA$51,,$A4);ScoreMatrix!G$2:G$51},false),RankScores!$A$1:$C$100,3,false)),),)} | O4: {=if(and($G4<>O$2,$G4<>"",O$2<>""),sum(iferror(vlookup(rank(index(ScoreMatrix!$B$2:$AA$51,,$A4),{index(ScoreMatrix!$B$2:$AA$51,,$A4);ScoreMatrix!H$2:H$51},false),RankScores!$A$1:$C$100,3,false)),),)} | P4: {=if(and($G4<>P$2,$G4<>"",P$2<>""),sum(iferror(vlookup(rank(index(ScoreMatrix!$B$2:$AA$51,,$A4),{index(ScoreMatrix!$B$2:$AA$51,,$A4);ScoreMatrix!I$2:I$51},false),RankScores!$A$1:$C$100,3,false)),),)} | ... AF4: {=if(and($G4<>AF$2,$G4<>"",AF$2<>""),sum(iferror(vlookup(rank(index(ScoreMatrix!$B$2:$AA$51,,$A4),{index(ScoreMatrix!$B$2:$AA$51,,$A4);ScoreMatrix!Y$2:Y$51},false),RankScores!$A$1:$C$100,3,false)),),)}
A5: 3 | B5: =if(isblank(VirtualLeague!D5),,"`"&VirtualLeague!C5&rept(" ",20-len(VirtualLeague!C5))& rept(" ",6-len(VirtualLeague!D5))&VirtualLeague!D5&"`" ) -> `NORTH 3903` | C5: NORTH | D5: 3903 | E5: {=if(G5="",,count(index(ScoreMatrix!$B$2:$AA$51,,$A5)))} -> 49 | F5: {=if(G5="",,average(index(ScoreMatrix!$B$2:$AA$51,,$A5)))} -> 38493.612 | G5: =index($I$2:$AF$2,A5) -> pl | H5: =if(G5="",,sum(I5:AF5)) -> 10947 | I5: {=if(and($G5<>I$2,$G5<>"",I$2<>""),sum(iferror(vlookup(rank(index(ScoreMatrix!$B$2:$AA$51,,$A5),{index(ScoreMatrix!$B$2:$AA$51,,$A5);ScoreMatrix!B$2:B$51},false),RankScores!$A$1:$C$100,3,false)),),)} -> 4314 | J5: {=if(and($G5<>J$2,$G5<>"",J$2<>""),sum(iferror(vlookup(rank(index(ScoreMatrix!$B$2:$AA$51,,$A5),{index(ScoreMatrix!$B$2:$AA$51,,$A5);ScoreMatrix!C$2:C$51},false),RankScores!$A$1:$C$100,3,false)),),)} -> 4249 | K5: {=if(and($G5<>K$2,$G5<>"",K$2<>""),sum(iferror(vlookup(rank(index(ScoreMatrix!$B$2:$AA$51,,$A5),{index(ScoreMatrix!$B$2:$AA$51,,$A5);ScoreMatrix!D$2:D$51},false),RankScores!$A$1:$C$100,3,false)),),)} | L5: {=if(and($G5<>L$2,$G5<>"",L$2<>""),sum(iferror(vlookup(rank(index(ScoreMatrix!$B$2:$AA$51,,$A5),{index(ScoreMatrix!$B$2:$AA$51,,$A5);ScoreMatrix!E$2:E$51},false),RankScores!$A$1:$C$100,3,false)),),)} -> 2384 | M5: {=if(and($G5<>M$2,$G5<>"",M$2<>""),sum(iferror(vlookup(rank(index(ScoreMatrix!$B$2:$AA$51,,$A5),{index(ScoreMatrix!$B$2:$AA$51,,$A5);ScoreMatrix!F$2:F$51},false),RankScores!$A$1:$C$100,3,false)),),)} | N5: {=if(and($G5<>N$2,$G5<>"",N$2<>""),sum(iferror(vlookup(rank(index(ScoreMatrix!$B$2:$AA$51,,$A5),{index(ScoreMatrix!$B$2:$AA$51,,$A5);ScoreMatrix!G$2:G$51},false),RankScores!$A$1:$C$100,3,false)),),)} | O5: {=if(and($G5<>O$2,$G5<>"",O$2<>""),sum(iferror(vlookup(rank(index(ScoreMatrix!$B$2:$AA$51,,$A5),{index(ScoreMatrix!$B$2:$AA$51,,$A5);ScoreMatrix!H$2:H$51},false),RankScores!$A$1:$C$100,3,false)),),)} | P5: {=if(and($G5<>P$2,$G5<>"",P$2<>""),sum(iferror(vlookup(rank(index(ScoreMatrix!$B$2:$AA$51,,$A5),{index(ScoreMatrix!$B$2:$AA$51,,$A5);ScoreMatrix!I$2:I$51},false),RankScores!$A$1:$C$100,3,false)),),)} | ... AF5: {=if(and($G5<>AF$2,$G5<>"",AF$2<>""),sum(iferror(vlookup(rank(index(ScoreMatrix!$B$2:$AA$51,,$A5),{index(ScoreMatrix!$B$2:$AA$51,,$A5);ScoreMatrix!Y$2:Y$51},false),RankScores!$A$1:$C$100,3,false)),),)}
A6: 4 | B6: =if(isblank(VirtualLeague!D6),,"`"&VirtualLeague!C6&rept(" ",20-len(VirtualLeague!C6))& rept(" ",6-len(VirtualLeague!D6))&VirtualLeague!D6&"`" ) -> `Greddit2 1582` | C6: Greddit2 | D6: 1582 | E6: {=if(G6="",,count(index(ScoreMatrix!$B$2:$AA$51,,$A6)))} -> 50 | F6: {=if(G6="",,average(index(ScoreMatrix!$B$2:$AA$51,,$A6)))} -> 37560.44 | G6: =index($I$2:$AF$2,A6) -> sebg | H6: =if(G6="",,sum(I6:AF6)) -> 10713 | I6: {=if(and($G6<>I$2,$G6<>"",I$2<>""),sum(iferror(vlookup(rank(index(ScoreMatrix!$B$2:$AA$51,,$A6),{index(ScoreMatrix!$B$2:$AA$51,,$A6);ScoreMatrix!B$2:B$51},false),RankScores!$A$1:$C$100,3,false)),),)} -> 4309 | J6: {=if(and($G6<>J$2,$G6<>"",J$2<>""),sum(iferror(vlookup(rank(index(ScoreMatrix!$B$2:$AA$51,,$A6),{index(ScoreMatrix!$B$2:$AA$51,,$A6);ScoreMatrix!C$2:C$51},false),RankScores!$A$1:$C$100,3,false)),),)} -> 4262 | K6: {=if(and($G6<>K$2,$G6<>"",K$2<>""),sum(iferror(vlookup(rank(index(ScoreMatrix!$B$2:$AA$51,,$A6),{index(ScoreMatrix!$B$2:$AA$51,,$A6);ScoreMatrix!D$2:D$51},false),RankScores!$A$1:$C$100,3,false)),),)} -> 2142 | L6: {=if(and($G6<>L$2,$G6<>"",L$2<>""),sum(iferror(vlookup(rank(index(ScoreMatrix!$B$2:$AA$51,,$A6),{index(ScoreMatrix!$B$2:$AA$51,,$A6);ScoreMatrix!E$2:E$51},false),RankScores!$A$1:$C$100,3,false)),),)} | M6: {=if(and($G6<>M$2,$G6<>"",M$2<>""),sum(iferror(vlookup(rank(index(ScoreMatrix!$B$2:$AA$51,,$A6),{index(ScoreMatrix!$B$2:$AA$51,,$A6);ScoreMatrix!F$2:F$51},false),RankScores!$A$1:$C$100,3,false)),),)} | N6: {=if(and($G6<>N$2,$G6<>"",N$2<>""),sum(iferror(vlookup(rank(index(ScoreMatrix!$B$2:$AA$51,,$A6),{index(ScoreMatrix!$B$2:$AA$51,,$A6);ScoreMatrix!G$2:G$51},false),RankScores!$A$1:$C$100,3,false)),),)} | O6: {=if(and($G6<>O$2,$G6<>"",O$2<>""),sum(iferror(vlookup(rank(index(ScoreMatrix!$B$2:$AA$51,,$A6),{index(ScoreMatrix!$B$2:$AA$51,,$A6);ScoreMatrix!H$2:H$51},false),RankScores!$A$1:$C$100,3,false)),),)} | P6: {=if(and($G6<>P$2,$G6<>"",P$2<>""),sum(iferror(vlookup(rank(index(ScoreMatrix!$B$2:$AA$51,,$A6),{index(ScoreMatrix!$B$2:$AA$51,,$A6);ScoreMatrix!I$2:I$51},false),RankScores!$A$1:$C$100,3,false)),),)} | ... AF6: {=if(and($G6<>AF$2,$G6<>"",AF$2<>""),sum(iferror(vlookup(rank(index(ScoreMatrix!$B$2:$AA$51,,$A6),{index(ScoreMatrix!$B$2:$AA$51,,$A6);ScoreMatrix!Y$2:Y$51},false),RankScores!$A$1:$C$100,3,false)),),)}
A7: 5 | B7: =if(isblank(VirtualLeague!D7),,"`"&VirtualLeague!C7&rept(" ",20-len(VirtualLeague!C7))& rept(" ",6-len(VirtualLeague!D7))&VirtualLeague!D7&"`" ) | E7: {=if(G7="",,count(index(ScoreMatrix!$B$2:$AA$51,,$A7)))} | F7: {=if(G7="",,average(index(ScoreMatrix!$B$2:$AA$51,,$A7)))} | G7: =index($I$2:$AF$2,A7) | H7: =if(G7="",,sum(I7:AF7)) | I7: {=if(and($G7<>I$2,$G7<>"",I$2<>""),sum(iferror(vlookup(rank(index(ScoreMatrix!$B$2:$AA$51,,$A7),{index(ScoreMatrix!$B$2:$AA$51,,$A7);ScoreMatrix!B$2:B$51},false),RankScores!$A$1:$C$100,3,false)),),)} | J7: {=if(and($G7<>J$2,$G7<>"",J$2<>""),sum(iferror(vlookup(rank(index(ScoreMatrix!$B$2:$AA$51,,$A7),{index(ScoreMatrix!$B$2:$AA$51,,$A7);ScoreMatrix!C$2:C$51},false),RankScores!$A$1:$C$100,3,false)),),)} | K7: {=if(and($G7<>K$2,$G7<>"",K$2<>""),sum(iferror(vlookup(rank(index(ScoreMatrix!$B$2:$AA$51,,$A7),{index(ScoreMatrix!$B$2:$AA$51,,$A7);ScoreMatrix!D$2:D$51},false),RankScores!$A$1:$C$100,3,false)),),)} | L7: {=if(and($G7<>L$2,$G7<>"",L$2<>""),sum(iferror(vlookup(rank(index(ScoreMatrix!$B$2:$AA$51,,$A7),{index(ScoreMatrix!$B$2:$AA$51,,$A7);ScoreMatrix!E$2:E$51},false),RankScores!$A$1:$C$100,3,false)),),)} | M7: {=if(and($G7<>M$2,$G7<>"",M$2<>""),sum(iferror(vlookup(rank(index(ScoreMatrix!$B$2:$AA$51,,$A7),{index(ScoreMatrix!$B$2:$AA$51,,$A7);ScoreMatrix!F$2:F$51},false),RankScores!$A$1:$C$100,3,false)),),)} | N7: {=if(and($G7<>N$2,$G7<>"",N$2<>""),sum(iferror(vlookup(rank(index(ScoreMatrix!$B$2:$AA$51,,$A7),{index(ScoreMatrix!$B$2:$AA$51,,$A7);ScoreMatrix!G$2:G$51},false),RankScores!$A$1:$C$100,3,false)),),)} | O7: {=if(and($G7<>O$2,$G7<>"",O$2<>""),sum(iferror(vlookup(rank(index(ScoreMatrix!$B$2:$AA$51,,$A7),{index(ScoreMatrix!$B$2:$AA$51,,$A7);ScoreMatrix!H$2:H$51},false),RankScores!$A$1:$C$100,3,false)),),)} | P7: {=if(and($G7<>P$2,$G7<>"",P$2<>""),sum(iferror(vlookup(rank(index(ScoreMatrix!$B$2:$AA$51,,$A7),{index(ScoreMatrix!$B$2:$AA$51,,$A7);ScoreMatrix!I$2:I$51},false),RankScores!$A$1:$C$100,3,false)),),)} | ... AF7: {=if(and($G7<>AF$2,$G7<>"",AF$2<>""),sum(iferror(vlookup(rank(index(ScoreMatrix!$B$2:$AA$51,,$A7),{index(ScoreMatrix!$B$2:$AA$51,,$A7);ScoreMatrix!Y$2:Y$51},false),RankScores!$A$1:$C$100,3,false)),),)}
A8: 6 | B8: =if(isblank(VirtualLeague!D8),,"`"&VirtualLeague!C8&rept(" ",20-len(VirtualLeague!C8))& rept(" ",6-len(VirtualLeague!D8))&VirtualLeague!D8&"`" ) | E8: {=if(G8="",,count(index(ScoreMatrix!$B$2:$AA$51,,$A8)))} | F8: {=if(G8="",,average(index(ScoreMatrix!$B$2:$AA$51,,$A8)))} | G8: =index($I$2:$AF$2,A8) | H8: =if(G8="",,sum(I8:AF8)) | I8: {=if(and($G8<>I$2,$G8<>"",I$2<>""),sum(iferror(vlookup(rank(index(ScoreMatrix!$B$2:$AA$51,,$A8),{index(ScoreMatrix!$B$2:$AA$51,,$A8);ScoreMatrix!B$2:B$51},false),RankScores!$A$1:$C$100,3,false)),),)} | J8: {=if(and($G8<>J$2,$G8<>"",J$2<>""),sum(iferror(vlookup(rank(index(ScoreMatrix!$B$2:$AA$51,,$A8),{index(ScoreMatrix!$B$2:$AA$51,,$A8);ScoreMatrix!C$2:C$51},false),RankScores!$A$1:$C$100,3,false)),),)} | K8: {=if(and($G8<>K$2,$G8<>"",K$2<>""),sum(iferror(vlookup(rank(index(ScoreMatrix!$B$2:$AA$51,,$A8),{index(ScoreMatrix!$B$2:$AA$51,,$A8);ScoreMatrix!D$2:D$51},false),RankScores!$A$1:$C$100,3,false)),),)} | L8: {=if(and($G8<>L$2,$G8<>"",L$2<>""),sum(iferror(vlookup(rank(index(ScoreMatrix!$B$2:$AA$51,,$A8),{index(ScoreMatrix!$B$2:$AA$51,,$A8);ScoreMatrix!E$2:E$51},false),RankScores!$A$1:$C$100,3,false)),),)} | M8: {=if(and($G8<>M$2,$G8<>"",M$2<>""),sum(iferror(vlookup(rank(index(ScoreMatrix!$B$2:$AA$51,,$A8),{index(ScoreMatrix!$B$2:$AA$51,,$A8);ScoreMatrix!F$2:F$51},false),RankScores!$A$1:$C$100,3,false)),),)} | N8: {=if(and($G8<>N$2,$G8<>"",N$2<>""),sum(iferror(vlookup(rank(index(ScoreMatrix!$B$2:$AA$51,,$A8),{index(ScoreMatrix!$B$2:$AA$51,,$A8);ScoreMatrix!G$2:G$51},false),RankScores!$A$1:$C$100,3,false)),),)} | O8: {=if(and($G8<>O$2,$G8<>"",O$2<>""),sum(iferror(vlookup(rank(index(ScoreMatrix!$B$2:$AA$51,,$A8),{index(ScoreMatrix!$B$2:$AA$51,,$A8);ScoreMatrix!H$2:H$51},false),RankScores!$A$1:$C$100,3,false)),),)} | P8: {=if(and($G8<>P$2,$G8<>"",P$2<>""),sum(iferror(vlookup(rank(index(ScoreMatrix!$B$2:$AA$51,,$A8),{index(ScoreMatrix!$B$2:$AA$51,,$A8);ScoreMatrix!I$2:I$51},false),RankScores!$A$1:$C$100,3,false)),),)} | ... AF8: {=if(and($G8<>AF$2,$G8<>"",AF$2<>""),sum(iferror(vlookup(rank(index(ScoreMatrix!$B$2:$AA$51,,$A8),{index(ScoreMatrix!$B$2:$AA$51,,$A8);ScoreMatrix!Y$2:Y$51},false),RankScores!$A$1:$C$100,3,false)),),)}
A9: 7 | B9: =if(isblank(VirtualLeague!D9),,"`"&VirtualLeague!C9&rept(" ",20-len(VirtualLeague!C9))& rept(" ",6-len(VirtualLeague!D9))&VirtualLeague!D9&"`" ) | E9: {=if(G9="",,count(index(ScoreMatrix!$B$2:$AA$51,,$A9)))} | F9: {=if(G9="",,average(index(ScoreMatrix!$B$2:$AA$51,,$A9)))} | G9: =index($I$2:$AF$2,A9) | H9: =if(G9="",,sum(I9:AF9)) | I9: {=if(and($G9<>I$2,$G9<>"",I$2<>""),sum(iferror(vlookup(rank(index(ScoreMatrix!$B$2:$AA$51,,$A9),{index(ScoreMatrix!$B$2:$AA$51,,$A9);ScoreMatrix!B$2:B$51},false),RankScores!$A$1:$C$100,3,false)),),)} | J9: {=if(and($G9<>J$2,$G9<>"",J$2<>""),sum(iferror(vlookup(rank(index(ScoreMatrix!$B$2:$AA$51,,$A9),{index(ScoreMatrix!$B$2:$AA$51,,$A9);ScoreMatrix!C$2:C$51},false),RankScores!$A$1:$C$100,3,false)),),)} | K9: {=if(and($G9<>K$2,$G9<>"",K$2<>""),sum(iferror(vlookup(rank(index(ScoreMatrix!$B$2:$AA$51,,$A9),{index(ScoreMatrix!$B$2:$AA$51,,$A9);ScoreMatrix!D$2:D$51},false),RankScores!$A$1:$C$100,3,false)),),)} | L9: {=if(and($G9<>L$2,$G9<>"",L$2<>""),sum(iferror(vlookup(rank(index(ScoreMatrix!$B$2:$AA$51,,$A9),{index(ScoreMatrix!$B$2:$AA$51,,$A9);ScoreMatrix!E$2:E$51},false),RankScores!$A$1:$C$100,3,false)),),)} | M9: {=if(and($G9<>M$2,$G9<>"",M$2<>""),sum(iferror(vlookup(rank(index(ScoreMatrix!$B$2:$AA$51,,$A9),{index(ScoreMatrix!$B$2:$AA$51,,$A9);ScoreMatrix!F$2:F$51},false),RankScores!$A$1:$C$100,3,false)),),)} | N9: {=if(and($G9<>N$2,$G9<>"",N$2<>""),sum(iferror(vlookup(rank(index(ScoreMatrix!$B$2:$AA$51,,$A9),{index(ScoreMatrix!$B$2:$AA$51,,$A9);ScoreMatrix!G$2:G$51},false),RankScores!$A$1:$C$100,3,false)),),)} | O9: {=if(and($G9<>O$2,$G9<>"",O$2<>""),sum(iferror(vlookup(rank(index(ScoreMatrix!$B$2:$AA$51,,$A9),{index(ScoreMatrix!$B$2:$AA$51,,$A9);ScoreMatrix!H$2:H$51},false),RankScores!$A$1:$C$100,3,false)),),)} | P9: {=if(and($G9<>P$2,$G9<>"",P$2<>""),sum(iferror(vlookup(rank(index(ScoreMatrix!$B$2:$AA$51,,$A9),{index(ScoreMatrix!$B$2:$AA$51,,$A9);ScoreMatrix!I$2:I$51},false),RankScores!$A$1:$C$100,3,false)),),)} | ... AF9: {=if(and($G9<>AF$2,$G9<>"",AF$2<>""),sum(iferror(vlookup(rank(index(ScoreMatrix!$B$2:$AA$51,,$A9),{index(ScoreMatrix!$B$2:$AA$51,,$A9);ScoreMatrix!Y$2:Y$51},false),RankScores!$A$1:$C$100,3,false)),),)}
A10: 8 | B10: =if(isblank(VirtualLeague!D10),,"`"&VirtualLeague!C10&rept(" ",20-len(VirtualLeague!C10))& rept(" ",6-len(VirtualLeague!D10))&VirtualLeague!D10&"`" ) | E10: {=if(G10="",,count(index(ScoreMatrix!$B$2:$AA$51,,$A10)))} | F10: {=if(G10="",,average(index(ScoreMatrix!$B$2:$AA$51,,$A10)))} | G10: =index($I$2:$AF$2,A10) | H10: =if(G10="",,sum(I10:AF10)) | I10: {=if(and($G10<>I$2,$G10<>"",I$2<>""),sum(iferror(vlookup(rank(index(ScoreMatrix!$B$2:$AA$51,,$A10),{index(ScoreMatrix!$B$2:$AA$51,,$A10);ScoreMatrix!B$2:B$51},false),RankScores!$A$1:$C$100,3,false)),),)} | J10: {=if(and($G10<>J$2,$G10<>"",J$2<>""),sum(iferror(vlookup(rank(index(ScoreMatrix!$B$2:$AA$51,,$A10),{index(ScoreMatrix!$B$2:$AA$51,,$A10);ScoreMatrix!C$2:C$51},false),RankScores!$A$1:$C$100,3,false)),),)} | K10: {=if(and($G10<>K$2,$G10<>"",K$2<>""),sum(iferror(vlookup(rank(index(ScoreMatrix!$B$2:$AA$51,,$A10),{index(ScoreMatrix!$B$2:$AA$51,,$A10);ScoreMatrix!D$2:D$51},false),RankScores!$A$1:$C$100,3,false)),),)} | L10: {=if(and($G10<>L$2,$G10<>"",L$2<>""),sum(iferror(vlookup(rank(index(ScoreMatrix!$B$2:$AA$51,,$A10),{index(ScoreMatrix!$B$2:$AA$51,,$A10);ScoreMatrix!E$2:E$51},false),RankScores!$A$1:$C$100,3,false)),),)} | M10: {=if(and($G10<>M$2,$G10<>"",M$2<>""),sum(iferror(vlookup(rank(index(ScoreMatrix!$B$2:$AA$51,,$A10),{index(ScoreMatrix!$B$2:$AA$51,,$A10);ScoreMatrix!F$2:F$51},false),RankScores!$A$1:$C$100,3,false)),),)} | N10: {=if(and($G10<>N$2,$G10<>"",N$2<>""),sum(iferror(vlookup(rank(index(ScoreMatrix!$B$2:$AA$51,,$A10),{index(ScoreMatrix!$B$2:$AA$51,,$A10);ScoreMatrix!G$2:G$51},false),RankScores!$A$1:$C$100,3,false)),),)} | O10: {=if(and($G10<>O$2,$G10<>"",O$2<>""),sum(iferror(vlookup(rank(index(ScoreMatrix!$B$2:$AA$51,,$A10),{index(ScoreMatrix!$B$2:$AA$51,,$A10);ScoreMatrix!H$2:H$51},false),RankScores!$A$1:$C$100,3,false)),),)} | P10: {=if(and($G10<>P$2,$G10<>"",P$2<>""),sum(iferror(vlookup(rank(index(ScoreMatrix!$B$2:$AA$51,,$A10),{index(ScoreMatrix!$B$2:$AA$51,,$A10);ScoreMatrix!I$2:I$51},false),RankScores!$A$1:$C$100,3,false)),),)} | ... AF10: {=if(and($G10<>AF$2,$G10<>"",AF$2<>""),sum(iferror(vlookup(rank(index(ScoreMatrix!$B$2:$AA$51,,$A10),{index(ScoreMatrix!$B$2:$AA$51,,$A10);ScoreMatrix!Y$2:Y$51},false),RankScores!$A$1:$C$100,3,false)),),)}
A11: 9 | B11: =if(isblank(VirtualLeague!D11),,"`"&VirtualLeague!C11&rept(" ",20-len(VirtualLeague!C11))& rept(" ",6-len(VirtualLeague!D11))&VirtualLeague!D11&"`" ) | E11: {=if(G11="",,count(index(ScoreMatrix!$B$2:$AA$51,,$A11)))} | F11: {=if(G11="",,average(index(ScoreMatrix!$B$2:$AA$51,,$A11)))} | G11: =index($I$2:$AF$2,A11) | H11: =if(G11="",,sum(I11:AF11)) | I11: {=if(and($G11<>I$2,$G11<>"",I$2<>""),sum(iferror(vlookup(rank(index(ScoreMatrix!$B$2:$AA$51,,$A11),{index(ScoreMatrix!$B$2:$AA$51,,$A11);ScoreMatrix!B$2:B$51},false),RankScores!$A$1:$C$100,3,false)),),)} | J11: {=if(and($G11<>J$2,$G11<>"",J$2<>""),sum(iferror(vlookup(rank(index(ScoreMatrix!$B$2:$AA$51,,$A11),{index(ScoreMatrix!$B$2:$AA$51,,$A11);ScoreMatrix!C$2:C$51},false),RankScores!$A$1:$C$100,3,false)),),)} | K11: {=if(and($G11<>K$2,$G11<>"",K$2<>""),sum(iferror(vlookup(rank(index(ScoreMatrix!$B$2:$AA$51,,$A11),{index(ScoreMatrix!$B$2:$AA$51,,$A11);ScoreMatrix!D$2:D$51},false),RankScores!$A$1:$C$100,3,false)),),)} | L11: {=if(and($G11<>L$2,$G11<>"",L$2<>""),sum(iferror(vlookup(rank(index(ScoreMatrix!$B$2:$AA$51,,$A11),{index(ScoreMatrix!$B$2:$AA$51,,$A11);ScoreMatrix!E$2:E$51},false),RankScores!$A$1:$C$100,3,false)),),)} | M11: {=if(and($G11<>M$2,$G11<>"",M$2<>""),sum(iferror(vlookup(rank(index(ScoreMatrix!$B$2:$AA$51,,$A11),{index(ScoreMatrix!$B$2:$AA$51,,$A11);ScoreMatrix!F$2:F$51},false),RankScores!$A$1:$C$100,3,false)),),)} | N11: {=if(and($G11<>N$2,$G11<>"",N$2<>""),sum(iferror(vlookup(rank(index(ScoreMatrix!$B$2:$AA$51,,$A11),{index(ScoreMatrix!$B$2:$AA$51,,$A11);ScoreMatrix!G$2:G$51},false),RankScores!$A$1:$C$100,3,false)),),)} | O11: {=if(and($G11<>O$2,$G11<>"",O$2<>""),sum(iferror(vlookup(rank(index(ScoreMatrix!$B$2:$AA$51,,$A11),{index(ScoreMatrix!$B$2:$AA$51,,$A11);ScoreMatrix!H$2:H$51},false),RankScores!$A$1:$C$100,3,false)),),)} | P11: {=if(and($G11<>P$2,$G11<>"",P$2<>""),sum(iferror(vlookup(rank(index(ScoreMatrix!$B$2:$AA$51,,$A11),{index(ScoreMatrix!$B$2:$AA$51,,$A11);ScoreMatrix!I$2:I$51},false),RankScores!$A$1:$C$100,3,false)),),)} | ... AF11: {=if(and($G11<>AF$2,$G11<>"",AF$2<>""),sum(iferror(vlookup(rank(index(ScoreMatrix!$B$2:$AA$51,,$A11),{index(ScoreMatrix!$B$2:$AA$51,,$A11);ScoreMatrix!Y$2:Y$51},false),RankScores!$A$1:$C$100,3,false)),),)}
A12: 10 | B12: =if(isblank(VirtualLeague!D12),,"`"&VirtualLeague!C12&rept(" ",20-len(VirtualLeague!C12))& rept(" ",6-len(VirtualLeague!D12))&VirtualLeague!D12&"`" ) | E12: {=if(G12="",,count(index(ScoreMatrix!$B$2:$AA$51,,$A12)))} | F12: {=if(G12="",,average(index(ScoreMatrix!$B$2:$AA$51,,$A12)))} | G12: =index($I$2:$AF$2,A12) | H12: =if(G12="",,sum(I12:AF12)) | I12: {=if(and($G12<>I$2,$G12<>"",I$2<>""),sum(iferror(vlookup(rank(index(ScoreMatrix!$B$2:$AA$51,,$A12),{index(ScoreMatrix!$B$2:$AA$51,,$A12);ScoreMatrix!B$2:B$51},false),RankScores!$A$1:$C$100,3,false)),),)} | J12: {=if(and($G12<>J$2,$G12<>"",J$2<>""),sum(iferror(vlookup(rank(index(ScoreMatrix!$B$2:$AA$51,,$A12),{index(ScoreMatrix!$B$2:$AA$51,,$A12);ScoreMatrix!C$2:C$51},false),RankScores!$A$1:$C$100,3,false)),),)} | K12: {=if(and($G12<>K$2,$G12<>"",K$2<>""),sum(iferror(vlookup(rank(index(ScoreMatrix!$B$2:$AA$51,,$A12),{index(ScoreMatrix!$B$2:$AA$51,,$A12);ScoreMatrix!D$2:D$51},false),RankScores!$A$1:$C$100,3,false)),),)} | L12: {=if(and($G12<>L$2,$G12<>"",L$2<>""),sum(iferror(vlookup(rank(index(ScoreMatrix!$B$2:$AA$51,,$A12),{index(ScoreMatrix!$B$2:$AA$51,,$A12);ScoreMatrix!E$2:E$51},false),RankScores!$A$1:$C$100,3,false)),),)} | M12: {=if(and($G12<>M$2,$G12<>"",M$2<>""),sum(iferror(vlookup(rank(index(ScoreMatrix!$B$2:$AA$51,,$A12),{index(ScoreMatrix!$B$2:$AA$51,,$A12);ScoreMatrix!F$2:F$51},false),RankScores!$A$1:$C$100,3,false)),),)} | N12: {=if(and($G12<>N$2,$G12<>"",N$2<>""),sum(iferror(vlookup(rank(index(ScoreMatrix!$B$2:$AA$51,,$A12),{index(ScoreMatrix!$B$2:$AA$51,,$A12);ScoreMatrix!G$2:G$51},false),RankScores!$A$1:$C$100,3,false)),),)} | O12: {=if(and($G12<>O$2,$G12<>"",O$2<>""),sum(iferror(vlookup(rank(index(ScoreMatrix!$B$2:$AA$51,,$A12),{index(ScoreMatrix!$B$2:$AA$51,,$A12);ScoreMatrix!H$2:H$51},false),RankScores!$A$1:$C$100,3,false)),),)} | P12: {=if(and($G12<>P$2,$G12<>"",P$2<>""),sum(iferror(vlookup(rank(index(ScoreMatrix!$B$2:$AA$51,,$A12),{index(ScoreMatrix!$B$2:$AA$51,,$A12);ScoreMatrix!I$2:I$51},false),RankScores!$A$1:$C$100,3,false)),),)} | ... AF12: {=if(and($G12<>AF$2,$G12<>"",AF$2<>""),sum(iferror(vlookup(rank(index(ScoreMatrix!$B$2:$AA$51,,$A12),{index(ScoreMatrix!$B$2:$AA$51,,$A12);ScoreMatrix!Y$2:Y$51},false),RankScores!$A$1:$C$100,3,false)),),)}
A13: 11 | B13: =if(isblank(VirtualLeague!D13),,"`"&VirtualLeague!C13&rept(" ",20-len(VirtualLeague!C13))& rept(" ",6-len(VirtualLeague!D13))&VirtualLeague!D13&"`" ) | E13: {=if(G13="",,count(index(ScoreMatrix!$B$2:$AA$51,,$A13)))} | F13: {=if(G13="",,average(index(ScoreMatrix!$B$2:$AA$51,,$A13)))} | G13: =index($I$2:$AF$2,A13) | H13: =if(G13="",,sum(I13:AF13)) | I13: {=if(and($G13<>I$2,$G13<>"",I$2<>""),sum(iferror(vlookup(rank(index(ScoreMatrix!$B$2:$AA$51,,$A13),{index(ScoreMatrix!$B$2:$AA$51,,$A13);ScoreMatrix!B$2:B$51},false),RankScores!$A$1:$C$100,3,false)),),)} | J13: {=if(and($G13<>J$2,$G13<>"",J$2<>""),sum(iferror(vlookup(rank(index(ScoreMatrix!$B$2:$AA$51,,$A13),{index(ScoreMatrix!$B$2:$AA$51,,$A13);ScoreMatrix!C$2:C$51},false),RankScores!$A$1:$C$100,3,false)),),)} | K13: {=if(and($G13<>K$2,$G13<>"",K$2<>""),sum(iferror(vlookup(rank(index(ScoreMatrix!$B$2:$AA$51,,$A13),{index(ScoreMatrix!$B$2:$AA$51,,$A13);ScoreMatrix!D$2:D$51},false),RankScores!$A$1:$C$100,3,false)),),)} | L13: {=if(and($G13<>L$2,$G13<>"",L$2<>""),sum(iferror(vlookup(rank(index(ScoreMatrix!$B$2:$AA$51,,$A13),{index(ScoreMatrix!$B$2:$AA$51,,$A13);ScoreMatrix!E$2:E$51},false),RankScores!$A$1:$C$100,3,false)),),)} | M13: {=if(and($G13<>M$2,$G13<>"",M$2<>""),sum(iferror(vlookup(rank(index(ScoreMatrix!$B$2:$AA$51,,$A13),{index(ScoreMatrix!$B$2:$AA$51,,$A13);ScoreMatrix!F$2:F$51},false),RankScores!$A$1:$C$100,3,false)),),)} | N13: {=if(and($G13<>N$2,$G13<>"",N$2<>""),sum(iferror(vlookup(rank(index(ScoreMatrix!$B$2:$AA$51,,$A13),{index(ScoreMatrix!$B$2:$AA$51,,$A13);ScoreMatrix!G$2:G$51},false),RankScores!$A$1:$C$100,3,false)),),)} | O13: {=if(and($G13<>O$2,$G13<>"",O$2<>""),sum(iferror(vlookup(rank(index(ScoreMatrix!$B$2:$AA$51,,$A13),{index(ScoreMatrix!$B$2:$AA$51,,$A13);ScoreMatrix!H$2:H$51},false),RankScores!$A$1:$C$100,3,false)),),)} | P13: {=if(and($G13<>P$2,$G13<>"",P$2<>""),sum(iferror(vlookup(rank(index(ScoreMatrix!$B$2:$AA$51,,$A13),{index(ScoreMatrix!$B$2:$AA$51,,$A13);ScoreMatrix!I$2:I$51},false),RankScores!$A$1:$C$100,3,false)),),)} | ... AF13: {=if(and($G13<>AF$2,$G13<>"",AF$2<>""),sum(iferror(vlookup(rank(index(ScoreMatrix!$B$2:$AA$51,,$A13),{index(ScoreMatrix!$B$2:$AA$51,,$A13);ScoreMatrix!Y$2:Y$51},false),RankScores!$A$1:$C$100,3,false)),),)}
A14: 12 | B14: =if(isblank(VirtualLeague!D14),,"`"&VirtualLeague!C14&rept(" ",20-len(VirtualLeague!C14))& rept(" ",6-len(VirtualLeague!D14))&VirtualLeague!D14&"`" ) | E14: {=if(G14="",,count(index(ScoreMatrix!$B$2:$AA$51,,$A14)))} | F14: {=if(G14="",,average(index(ScoreMatrix!$B$2:$AA$51,,$A14)))} | G14: =index($I$2:$AF$2,A14) | H14: =if(G14="",,sum(I14:AF14)) | I14: {=if(and($G14<>I$2,$G14<>"",I$2<>""),sum(iferror(vlookup(rank(index(ScoreMatrix!$B$2:$AA$51,,$A14),{index(ScoreMatrix!$B$2:$AA$51,,$A14);ScoreMatrix!B$2:B$51},false),RankScores!$A$1:$C$100,3,false)),),)} | J14: {=if(and($G14<>J$2,$G14<>"",J$2<>""),sum(iferror(vlookup(rank(index(ScoreMatrix!$B$2:$AA$51,,$A14),{index(ScoreMatrix!$B$2:$AA$51,,$A14);ScoreMatrix!C$2:C$51},false),RankScores!$A$1:$C$100,3,false)),),)} | K14: {=if(and($G14<>K$2,$G14<>"",K$2<>""),sum(iferror(vlookup(rank(index(ScoreMatrix!$B$2:$AA$51,,$A14),{index(ScoreMatrix!$B$2:$AA$51,,$A14);ScoreMatrix!D$2:D$51},false),RankScores!$A$1:$C$100,3,false)),),)} | L14: {=if(and($G14<>L$2,$G14<>"",L$2<>""),sum(iferror(vlookup(rank(index(ScoreMatrix!$B$2:$AA$51,,$A14),{index(ScoreMatrix!$B$2:$AA$51,,$A14);ScoreMatrix!E$2:E$51},false),RankScores!$A$1:$C$100,3,false)),),)} | M14: {=if(and($G14<>M$2,$G14<>"",M$2<>""),sum(iferror(vlookup(rank(index(ScoreMatrix!$B$2:$AA$51,,$A14),{index(ScoreMatrix!$B$2:$AA$51,,$A14);ScoreMatrix!F$2:F$51},false),RankScores!$A$1:$C$100,3,false)),),)} | N14: {=if(and($G14<>N$2,$G14<>"",N$2<>""),sum(iferror(vlookup(rank(index(ScoreMatrix!$B$2:$AA$51,,$A14),{index(ScoreMatrix!$B$2:$AA$51,,$A14);ScoreMatrix!G$2:G$51},false),RankScores!$A$1:$C$100,3,false)),),)} | O14: {=if(and($G14<>O$2,$G14<>"",O$2<>""),sum(iferror(vlookup(rank(index(ScoreMatrix!$B$2:$AA$51,,$A14),{index(ScoreMatrix!$B$2:$AA$51,,$A14);ScoreMatrix!H$2:H$51},false),RankScores!$A$1:$C$100,3,false)),),)} | P14: {=if(and($G14<>P$2,$G14<>"",P$2<>""),sum(iferror(vlookup(rank(index(ScoreMatrix!$B$2:$AA$51,,$A14),{index(ScoreMatrix!$B$2:$AA$51,,$A14);ScoreMatrix!I$2:I$51},false),RankScores!$A$1:$C$100,3,false)),),)} | ... AF14: {=if(and($G14<>AF$2,$G14<>"",AF$2<>""),sum(iferror(vlookup(rank(index(ScoreMatrix!$B$2:$AA$51,,$A14),{index(ScoreMatrix!$B$2:$AA$51,,$A14);ScoreMatrix!Y$2:Y$51},false),RankScores!$A$1:$C$100,3,false)),),)}
A15: 13 | B15: =if(isblank(VirtualLeague!D15),,"`"&VirtualLeague!C15&rept(" ",20-len(VirtualLeague!C15))& rept(" ",6-len(VirtualLeague!D15))&VirtualLeague!D15&"`" ) | E15: {=if(G15="",,count(index(ScoreMatrix!$B$2:$AA$51,,$A15)))} | F15: {=if(G15="",,average(index(ScoreMatrix!$B$2:$AA$51,,$A15)))} | G15: =index($I$2:$AF$2,A15) | H15: =if(G15="",,sum(I15:AF15)) | I15: {=if(and($G15<>I$2,$G15<>"",I$2<>""),sum(iferror(vlookup(rank(index(ScoreMatrix!$B$2:$AA$51,,$A15),{index(ScoreMatrix!$B$2:$AA$51,,$A15);ScoreMatrix!B$2:B$51},false),RankScores!$A$1:$C$100,3,false)),),)} | J15: {=if(and($G15<>J$2,$G15<>"",J$2<>""),sum(iferror(vlookup(rank(index(ScoreMatrix!$B$2:$AA$51,,$A15),{index(ScoreMatrix!$B$2:$AA$51,,$A15);ScoreMatrix!C$2:C$51},false),RankScores!$A$1:$C$100,3,false)),),)} | K15: {=if(and($G15<>K$2,$G15<>"",K$2<>""),sum(iferror(vlookup(rank(index(ScoreMatrix!$B$2:$AA$51,,$A15),{index(ScoreMatrix!$B$2:$AA$51,,$A15);ScoreMatrix!D$2:D$51},false),RankScores!$A$1:$C$100,3,false)),),)} | L15: {=if(and($G15<>L$2,$G15<>"",L$2<>""),sum(iferror(vlookup(rank(index(ScoreMatrix!$B$2:$AA$51,,$A15),{index(ScoreMatrix!$B$2:$AA$51,,$A15);ScoreMatrix!E$2:E$51},false),RankScores!$A$1:$C$100,3,false)),),)} | M15: {=if(and($G15<>M$2,$G15<>"",M$2<>""),sum(iferror(vlookup(rank(index(ScoreMatrix!$B$2:$AA$51,,$A15),{index(ScoreMatrix!$B$2:$AA$51,,$A15);ScoreMatrix!F$2:F$51},false),RankScores!$A$1:$C$100,3,false)),),)} | N15: {=if(and($G15<>N$2,$G15<>"",N$2<>""),sum(iferror(vlookup(rank(index(ScoreMatrix!$B$2:$AA$51,,$A15),{index(ScoreMatrix!$B$2:$AA$51,,$A15);ScoreMatrix!G$2:G$51},false),RankScores!$A$1:$C$100,3,false)),),)} | O15: {=if(and($G15<>O$2,$G15<>"",O$2<>""),sum(iferror(vlookup(rank(index(ScoreMatrix!$B$2:$AA$51,,$A15),{index(ScoreMatrix!$B$2:$AA$51,,$A15);ScoreMatrix!H$2:H$51},false),RankScores!$A$1:$C$100,3,false)),),)} | P15: {=if(and($G15<>P$2,$G15<>"",P$2<>""),sum(iferror(vlookup(rank(index(ScoreMatrix!$B$2:$AA$51,,$A15),{index(ScoreMatrix!$B$2:$AA$51,,$A15);ScoreMatrix!I$2:I$51},false),RankScores!$A$1:$C$100,3,false)),),)} | ... AF15: {=if(and($G15<>AF$2,$G15<>"",AF$2<>""),sum(iferror(vlookup(rank(index(ScoreMatrix!$B$2:$AA$51,,$A15),{index(ScoreMatrix!$B$2:$AA$51,,$A15);ScoreMatrix!Y$2:Y$51},false),RankScores!$A$1:$C$100,3,false)),),)}
A16: 14 | B16: =if(isblank(VirtualLeague!D16),,"`"&VirtualLeague!C16&rept(" ",20-len(VirtualLeague!C16))& rept(" ",6-len(VirtualLeague!D16))&VirtualLeague!D16&"`" ) | E16: {=if(G16="",,count(index(ScoreMatrix!$B$2:$AA$51,,$A16)))} | F16: {=if(G16="",,average(index(ScoreMatrix!$B$2:$AA$51,,$A16)))} | G16: =index($I$2:$AF$2,A16) | H16: =if(G16="",,sum(I16:AF16)) | I16: {=if(and($G16<>I$2,$G16<>"",I$2<>""),sum(iferror(vlookup(rank(index(ScoreMatrix!$B$2:$AA$51,,$A16),{index(ScoreMatrix!$B$2:$AA$51,,$A16);ScoreMatrix!B$2:B$51},false),RankScores!$A$1:$C$100,3,false)),),)} | J16: {=if(and($G16<>J$2,$G16<>"",J$2<>""),sum(iferror(vlookup(rank(index(ScoreMatrix!$B$2:$AA$51,,$A16),{index(ScoreMatrix!$B$2:$AA$51,,$A16);ScoreMatrix!C$2:C$51},false),RankScores!$A$1:$C$100,3,false)),),)} | K16: {=if(and($G16<>K$2,$G16<>"",K$2<>""),sum(iferror(vlookup(rank(index(ScoreMatrix!$B$2:$AA$51,,$A16),{index(ScoreMatrix!$B$2:$AA$51,,$A16);ScoreMatrix!D$2:D$51},false),RankScores!$A$1:$C$100,3,false)),),)} | L16: {=if(and($G16<>L$2,$G16<>"",L$2<>""),sum(iferror(vlookup(rank(index(ScoreMatrix!$B$2:$AA$51,,$A16),{index(ScoreMatrix!$B$2:$AA$51,,$A16);ScoreMatrix!E$2:E$51},false),RankScores!$A$1:$C$100,3,false)),),)} | M16: {=if(and($G16<>M$2,$G16<>"",M$2<>""),sum(iferror(vlookup(rank(index(ScoreMatrix!$B$2:$AA$51,,$A16),{index(ScoreMatrix!$B$2:$AA$51,,$A16);ScoreMatrix!F$2:F$51},false),RankScores!$A$1:$C$100,3,false)),),)} | N16: {=if(and($G16<>N$2,$G16<>"",N$2<>""),sum(iferror(vlookup(rank(index(ScoreMatrix!$B$2:$AA$51,,$A16),{index(ScoreMatrix!$B$2:$AA$51,,$A16);ScoreMatrix!G$2:G$51},false),RankScores!$A$1:$C$100,3,false)),),)} | O16: {=if(and($G16<>O$2,$G16<>"",O$2<>""),sum(iferror(vlookup(rank(index(ScoreMatrix!$B$2:$AA$51,,$A16),{index(ScoreMatrix!$B$2:$AA$51,,$A16);ScoreMatrix!H$2:H$51},false),RankScores!$A$1:$C$100,3,false)),),)} | P16: {=if(and($G16<>P$2,$G16<>"",P$2<>""),sum(iferror(vlookup(rank(index(ScoreMatrix!$B$2:$AA$51,,$A16),{index(ScoreMatrix!$B$2:$AA$51,,$A16);ScoreMatrix!I$2:I$51},false),RankScores!$A$1:$C$100,3,false)),),)} | ... AF16: {=if(and($G16<>AF$2,$G16<>"",AF$2<>""),sum(iferror(vlookup(rank(index(ScoreMatrix!$B$2:$AA$51,,$A16),{index(ScoreMatrix!$B$2:$AA$51,,$A16);ScoreMatrix!Y$2:Y$51},false),RankScores!$A$1:$C$100,3,false)),),)}
A17: 15 | B17: =if(isblank(VirtualLeague!D17),,"`"&VirtualLeague!C17&rept(" ",20-len(VirtualLeague!C17))& rept(" ",6-len(VirtualLeague!D17))&VirtualLeague!D17&"`" ) | E17: {=if(G17="",,count(index(ScoreMatrix!$B$2:$AA$51,,$A17)))} | F17: {=if(G17="",,average(index(ScoreMatrix!$B$2:$AA$51,,$A17)))} | G17: =index($I$2:$AF$2,A17) | H17: =if(G17="",,sum(I17:AF17)) | I17: {=if(and($G17<>I$2,$G17<>"",I$2<>""),sum(iferror(vlookup(rank(index(ScoreMatrix!$B$2:$AA$51,,$A17),{index(ScoreMatrix!$B$2:$AA$51,,$A17);ScoreMatrix!B$2:B$51},false),RankScores!$A$1:$C$100,3,false)),),)} | J17: {=if(and($G17<>J$2,$G17<>"",J$2<>""),sum(iferror(vlookup(rank(index(ScoreMatrix!$B$2:$AA$51,,$A17),{index(ScoreMatrix!$B$2:$AA$51,,$A17);ScoreMatrix!C$2:C$51},false),RankScores!$A$1:$C$100,3,false)),),)} | K17: {=if(and($G17<>K$2,$G17<>"",K$2<>""),sum(iferror(vlookup(rank(index(ScoreMatrix!$B$2:$AA$51,,$A17),{index(ScoreMatrix!$B$2:$AA$51,,$A17);ScoreMatrix!D$2:D$51},false),RankScores!$A$1:$C$100,3,false)),),)} | L17: {=if(and($G17<>L$2,$G17<>"",L$2<>""),sum(iferror(vlookup(rank(index(ScoreMatrix!$B$2:$AA$51,,$A17),{index(ScoreMatrix!$B$2:$AA$51,,$A17);ScoreMatrix!E$2:E$51},false),RankScores!$A$1:$C$100,3,false)),),)} | M17: {=if(and($G17<>M$2,$G17<>"",M$2<>""),sum(iferror(vlookup(rank(index(ScoreMatrix!$B$2:$AA$51,,$A17),{index(ScoreMatrix!$B$2:$AA$51,,$A17);ScoreMatrix!F$2:F$51},false),RankScores!$A$1:$C$100,3,false)),),)} | N17: {=if(and($G17<>N$2,$G17<>"",N$2<>""),sum(iferror(vlookup(rank(index(ScoreMatrix!$B$2:$AA$51,,$A17),{index(ScoreMatrix!$B$2:$AA$51,,$A17);ScoreMatrix!G$2:G$51},false),RankScores!$A$1:$C$100,3,false)),),)} | O17: {=if(and($G17<>O$2,$G17<>"",O$2<>""),sum(iferror(vlookup(rank(index(ScoreMatrix!$B$2:$AA$51,,$A17),{index(ScoreMatrix!$B$2:$AA$51,,$A17);ScoreMatrix!H$2:H$51},false),RankScores!$A$1:$C$100,3,false)),),)} | P17: {=if(and($G17<>P$2,$G17<>"",P$2<>""),sum(iferror(vlookup(rank(index(ScoreMatrix!$B$2:$AA$51,,$A17),{index(ScoreMatrix!$B$2:$AA$51,,$A17);ScoreMatrix!I$2:I$51},false),RankScores!$A$1:$C$100,3,false)),),)} | ... AF17: {=if(and($G17<>AF$2,$G17<>"",AF$2<>""),sum(iferror(vlookup(rank(index(ScoreMatrix!$B$2:$AA$51,,$A17),{index(ScoreMatrix!$B$2:$AA$51,,$A17);ScoreMatrix!Y$2:Y$51},false),RankScores!$A$1:$C$100,3,false)),),)}
A18: 16 | B18: =if(isblank(VirtualLeague!D18),,"`"&VirtualLeague!C18&rept(" ",20-len(VirtualLeague!C18))& rept(" ",6-len(VirtualLeague!D18))&VirtualLeague!D18&"`" ) | E18: {=if(G18="",,count(index(ScoreMatrix!$B$2:$AA$51,,$A18)))} | F18: {=if(G18="",,average(index(ScoreMatrix!$B$2:$AA$51,,$A18)))} | G18: =index($I$2:$AF$2,A18) | H18: =if(G18="",,sum(I18:AF18)) | I18: {=if(and($G18<>I$2,$G18<>"",I$2<>""),sum(iferror(vlookup(rank(index(ScoreMatrix!$B$2:$AA$51,,$A18),{index(ScoreMatrix!$B$2:$AA$51,,$A18);ScoreMatrix!B$2:B$51},false),RankScores!$A$1:$C$100,3,false)),),)} | J18: {=if(and($G18<>J$2,$G18<>"",J$2<>""),sum(iferror(vlookup(rank(index(ScoreMatrix!$B$2:$AA$51,,$A18),{index(ScoreMatrix!$B$2:$AA$51,,$A18);ScoreMatrix!C$2:C$51},false),RankScores!$A$1:$C$100,3,false)),),)} | K18: {=if(and($G18<>K$2,$G18<>"",K$2<>""),sum(iferror(vlookup(rank(index(ScoreMatrix!$B$2:$AA$51,,$A18),{index(ScoreMatrix!$B$2:$AA$51,,$A18);ScoreMatrix!D$2:D$51},false),RankScores!$A$1:$C$100,3,false)),),)} | L18: {=if(and($G18<>L$2,$G18<>"",L$2<>""),sum(iferror(vlookup(rank(index(ScoreMatrix!$B$2:$AA$51,,$A18),{index(ScoreMatrix!$B$2:$AA$51,,$A18);ScoreMatrix!E$2:E$51},false),RankScores!$A$1:$C$100,3,false)),),)} | M18: {=if(and($G18<>M$2,$G18<>"",M$2<>""),sum(iferror(vlookup(rank(index(ScoreMatrix!$B$2:$AA$51,,$A18),{index(ScoreMatrix!$B$2:$AA$51,,$A18);ScoreMatrix!F$2:F$51},false),RankScores!$A$1:$C$100,3,false)),),)} | N18: {=if(and($G18<>N$2,$G18<>"",N$2<>""),sum(iferror(vlookup(rank(index(ScoreMatrix!$B$2:$AA$51,,$A18),{index(ScoreMatrix!$B$2:$AA$51,,$A18);ScoreMatrix!G$2:G$51},false),RankScores!$A$1:$C$100,3,false)),),)} | O18: {=if(and($G18<>O$2,$G18<>"",O$2<>""),sum(iferror(vlookup(rank(index(ScoreMatrix!$B$2:$AA$51,,$A18),{index(ScoreMatrix!$B$2:$AA$51,,$A18);ScoreMatrix!H$2:H$51},false),RankScores!$A$1:$C$100,3,false)),),)} | P18: {=if(and($G18<>P$2,$G18<>"",P$2<>""),sum(iferror(vlookup(rank(index(ScoreMatrix!$B$2:$AA$51,,$A18),{index(ScoreMatrix!$B$2:$AA$51,,$A18);ScoreMatrix!I$2:I$51},false),RankScores!$A$1:$C$100,3,false)),),)} | ... AF18: {=if(and($G18<>AF$2,$G18<>"",AF$2<>""),sum(iferror(vlookup(rank(index(ScoreMatrix!$B$2:$AA$51,,$A18),{index(ScoreMatrix!$B$2:$AA$51,,$A18);ScoreMatrix!Y$2:Y$51},false),RankScores!$A$1:$C$100,3,false)),),)}
... A26: 24 | B26: =if(isblank(VirtualLeague!D26),,"`"&VirtualLeague!C26&rept(" ",20-len(VirtualLeague!C26))& rept(" ",6-len(VirtualLeague!D26))&VirtualLeague!D26&"`" ) | E26: {=if(G26="",,count(index(ScoreMatrix!$B$2:$AA$51,,$A26)))} | F26: {=if(G26="",,average(index(ScoreMatrix!$B$2:$AA$51,,$A26)))} | G26: =index($I$2:$AF$2,A26) | H26: =if(G26="",,sum(I26:AF26)) | I26: {=if(and($G26<>I$2,$G26<>"",I$2<>""),sum(iferror(vlookup(rank(index(ScoreMatrix!$B$2:$AA$51,,$A26),{index(ScoreMatrix!$B$2:$AA$51,,$A26);ScoreMatrix!B$2:B$51},false),RankScores!$A$1:$C$100,3,false)),),)} | J26: {=if(and($G26<>J$2,$G26<>"",J$2<>""),sum(iferror(vlookup(rank(index(ScoreMatrix!$B$2:$AA$51,,$A26),{index(ScoreMatrix!$B$2:$AA$51,,$A26);ScoreMatrix!C$2:C$51},false),RankScores!$A$1:$C$100,3,false)),),)} | K26: {=if(and($G26<>K$2,$G26<>"",K$2<>""),sum(iferror(vlookup(rank(index(ScoreMatrix!$B$2:$AA$51,,$A26),{index(ScoreMatrix!$B$2:$AA$51,,$A26);ScoreMatrix!D$2:D$51},false),RankScores!$A$1:$C$100,3,false)),),)} | L26: {=if(and($G26<>L$2,$G26<>"",L$2<>""),sum(iferror(vlookup(rank(index(ScoreMatrix!$B$2:$AA$51,,$A26),{index(ScoreMatrix!$B$2:$AA$51,,$A26);ScoreMatrix!E$2:E$51},false),RankScores!$A$1:$C$100,3,false)),),)} | M26: {=if(and($G26<>M$2,$G26<>"",M$2<>""),sum(iferror(vlookup(rank(index(ScoreMatrix!$B$2:$AA$51,,$A26),{index(ScoreMatrix!$B$2:$AA$51,,$A26);ScoreMatrix!F$2:F$51},false),RankScores!$A$1:$C$100,3,false)),),)} | N26: {=if(and($G26<>N$2,$G26<>"",N$2<>""),sum(iferror(vlookup(rank(index(ScoreMatrix!$B$2:$AA$51,,$A26),{index(ScoreMatrix!$B$2:$AA$51,,$A26);ScoreMatrix!G$2:G$51},false),RankScores!$A$1:$C$100,3,false)),),)} | O26: {=if(and($G26<>O$2,$G26<>"",O$2<>""),sum(iferror(vlookup(rank(index(ScoreMatrix!$B$2:$AA$51,,$A26),{index(ScoreMatrix!$B$2:$AA$51,,$A26);ScoreMatrix!H$2:H$51},false),RankScores!$A$1:$C$100,3,false)),),)} | P26: {=if(and($G26<>P$2,$G26<>"",P$2<>""),sum(iferror(vlookup(rank(index(ScoreMatrix!$B$2:$AA$51,,$A26),{index(ScoreMatrix!$B$2:$AA$51,,$A26);ScoreMatrix!I$2:I$51},false),RankScores!$A$1:$C$100,3,false)),),)} | ... AF26: {=if(and($G26<>AF$2,$G26<>"",AF$2<>""),sum(iferror(vlookup(rank(index(ScoreMatrix!$B$2:$AA$51,,$A26),{index(ScoreMatrix!$B$2:$AA$51,,$A26);ScoreMatrix!Y$2:Y$51},false),RankScores!$A$1:$C$100,3,false)),),)}

Sheet VirtualMatch
C1: =Match(C3,VirtualLeague!$G$3:$G$26,0) -> 2 | D1: =Match(D3,VirtualLeague!$G$3:$G$26,0) -> 1 | G1: Player Scores | I1: Ranks | K1: Team Score Contribution | M1: Combined | O1: Sorted
G2: Team 1 | H2: Team 2 | I2: Team 1 | J2: Team 2 | K2: Team 1 | L2: Team 2 | M2: Team | N2: Score | O2: Team | P2: Score
C3: NORTH | D3: Greddit2 | F3: 1 | G3: {=index(ScoreMatrix!$B$2:$AA$51,0,C$1)} -> 38399 | H3: {=index(ScoreMatrix!$B$2:$AA$51,0,D$1)} -> 37750 | I3: =rank(G3,$G$3:$H$52,false) -> 1 | J3: =rank(H3,$G$3:$H$52,false) -> 3 | K3: {=iferror(index(RankScores!$C$1:$C$100,I3),)} -> 300 | L3: {=iferror(index(RankScores!$C$1:$C$100,J3),)} -> 262 | M3: 1 | N3: =G3 -> 38399 | O3: {=sort(M3:N102, N3:N102,false)} -> 1 | P3: 38399
C4: =sum(K:K) -> 3364 | D4: =sum(L:L) -> 1158 | F4: =F3+1 -> 2 | G4: 38021 | H4: 36340 | I4: =rank(G4,$G$3:$H$52,false) -> 2 | J4: =rank(H4,$G$3:$H$52,false) -> 9 | K4: {=iferror(index(RankScores!$C$1:$C$100,I4),)} -> 280 | L4: {=iferror(index(RankScores!$C$1:$C$100,J4),)} -> 173 | M4: =M3 -> 1 | N4: =G4 -> 38021 | O4: 1 | P4: 38021
F5: =F4+1 -> 3 | G5: 37631 | H5: 36148 | I5: =rank(G5,$G$3:$H$52,false) -> 4 | J5: =rank(H5,$G$3:$H$52,false) -> 11 | K5: {=iferror(index(RankScores!$C$1:$C$100,I5),)} -> 244 | L5: {=iferror(index(RankScores!$C$1:$C$100,J5),)} -> 150 | M5: =M4 -> 1 | N5: =G5 -> 37631 | O5: 2 | P5: 37750
